Workbook

Sheet Summary
A1: C202 | B1: 46083 | C1: 46084 | D1: 46085 | E1: 46086 | F1: 46087 | G1: 46088 | H1: 46090 | I1: 46091 | J1: 46092 | K1: 46093 | L1: 46094 | M1: 46095 | N1: 46097 | O1: 46098 | P1: 46099 | Q1: 46100 | R1: 46101 | S1: 46102 | T1: 46104 | U1: 46105 | V1: 46106 | W1: 46107 | X1: 46108 | Y1: 46109 | Z1: 46111 | AA1: 46112 | AB1: 46113 | AC1: 46114 | AD1: 46115 | AE1: 46116 | AF1: 46118 | AG1: 46119 | AH1: 46120 | AI1: 46121 | AJ1: 46122 | AK1: 46123 | AL1: 46125 | AM1: 46126 | AN1: 46127 | AO1: 46128 | AP1: 46129 | AQ1: 46130 | AR1: 46132 | AS1: 46133 | AT1: 46134 | AU1: 46135 | AV1: 46136 | AW1: 46137 | AX1: 46139 | AY1: 46140 | AZ1: 46141 | BA1: 46142 | BB1: 46143 | BC1: 46146 | BD1: 46147 | BE1: 46148 | BF1: 46149 | BG1: 46150 | BH1: 46151 | BI1: 46153 | BJ1: 46154 | BK1: 46155 | BL1: 46156 | BM1: 46157 | BN1: 46158 | BO1: 46160 | BP1: 46161 | BQ1: 46162 | BR1: 46163 | BS1: 46164 | BT1: 46165 | BU1: 46167 | BV1: 46168 | BW1: 46169 | BX1: 46170 | BY1: 46171 | BZ1: 46172 | CA1: 46173 | DO1: C202 | DP1: W15(4/6~11) | DQ1: W16(4/13~18) | DR1: W17(4/20~25) | DU1: Failure Mode | DW1: Description | EA1: 原因 | EB1: 對策 | EC1: 進度
A2: Total Fail Rate | B2: 0.0074 | C2: 0.0058 | D2: 0.0044 | E2: 0.0027 | F2: 0.0073 | G2: 0.0242 | H2: 0.0082 | I2: 0.0033 | J2: 0.0062 | K2: 0.0114 | L2: 0.0092 | M2: 0.0049 | N2: 0.0385 | O2: 0.039 | P2: 0.0364 | Q2: 0.0596 | R2: 0.044 | S2: 0.0431 | T2: 0.0441 | U2: 0.0531 | V2: 3.36% | W2: 3.68% | X2: 8.92% | Y2: 11.32% | Z2: ='C202'!$B509 -> 5.97% | AA2: ='C202'!$B530 -> 5.29% | AB2: {=INDEX('C202'!$H:$H,5+(COLUMN()-28)*21)} -> 4.47% | AC2: {=INDEX('C202'!$H:$H,5+(COLUMN()-28)*21)} -> 3.91% | AD2: {=INDEX('C202'!$H:$H,5+(COLUMN()-28)*21)} -> 2.65% | AE2: {=INDEX('C202'!$H:$H,5+(COLUMN()-28)*21)} -> 6.22% | AF2: {=INDEX('C202'!$H:$H,5+(COLUMN()-28)*21)} -> 8.52% | AG2: {=INDEX('C202'!$H:$H,5+(COLUMN()-28)*21)} -> 10.61% | AH2: {=INDEX('C202'!$H:$H,5+(COLUMN()-28)*21)} -> 8.49% | AI2: {=INDEX('C202'!$H:$H,5+(COLUMN()-28)*21)} -> 7.19% | ... AY2: {=INDEX('C202'!$H:$H,5+(COLUMN()-28)*21)} -> 9.86% | AZ2: {=_xlfn.NUMBERVALUE(INDEX('C202'!$H:$H,5+(COLUMN()-28)*21))} -> 0.0911 | BA2: {=INDEX('C202'!$H:$H,5+(COLUMN()-28)*21)} -> 10.70% | BB2: {=_xlfn.NUMBERVALUE(INDEX('C202'!$N:$N,5+(COLUMN()-54)*21))} -> 0.0884 | BC2: {=_xlfn.NUMBERVALUE(INDEX('C202'!$N:$N,5+(COLUMN()-54)*21))} -> 0.1839 | BD2: {=_xlfn.NUMBERVALUE(INDEX('C202'!$N:$N,5+(COLUMN()-54)*21))} -> 0.0814 | BE2: {=_xlfn.NUMBERVALUE(INDEX('C202'!$N:$N,5+(COLUMN()-54)*21))} -> 0.1252 | BF2: {=_xlfn.NUMBERVALUE(INDEX('C202'!$N:$N,5+(COLUMN()-54)*21))} -> 0.0335 | BG2: {=_xlfn.NUMBERVALUE(INDEX('C202'!$N:$N,5+(COLUMN()-54)*21))} -> 0.0813 | BH2: {=_xlfn.NUMBERVALUE(INDEX('C202'!$N:$N,5+(COLUMN()-54)*21))} -> 0.0543 | BI2: {=_xlfn.NUMBERVALUE(INDEX('C202'!$N:$N,5+(COLUMN()-54)*21))} -> 0.0804 | ... CA2: {=_xlfn.NUMBERVALUE(INDEX('C202'!$N:$N,5+(COLUMN()-54)*21))} -> 0 | DO2: Total | DP2: {=INDEX('C202'!$H:$H,3+4*21)+INDEX('C202'!$H:$H,3+5*21)+INDEX('C202'!$H:$H,3+6*21)+INDEX('C202'!$H:$H,3+7*21)+INDEX('C202'!$H:$H,3+8*21)+INDEX('C202'!$H:$H,3+9*21)} -> 15818 | DQ2: {=INDEX('C202'!$H:$H,3+10*21)+INDEX('C202'!$H:$H,3+11*21)+INDEX('C202'!$H:$H,3+12*21)+INDEX('C202'!$H:$H,3+13*21)+INDEX('C202'!$H:$H,3+14*21)+INDEX('C202'!$H:$H,3+15*21)} -> 18303 | DR2: {=INDEX('C202'!$H:$H,3+16*21)+INDEX('C202'!$H:$H,3+17*21)+INDEX('C202'!$H:$H,3+18*21)+INDEX('C202'!$H:$H,3+19*21)+INDEX('C202'!$H:$H,3+20*21)+INDEX('C202'!$H:$H,3+21*21)} -> 18024 | DU2: 1 | DV2: 參數調用錯誤 | DW2: 單條線不同設備有多種參數組合 | EA2: 換線未確認測試參數 | EB2: 製造試線過程找TE確認duty | EC2: 試線TE確認duty | ED2: On-going
A3: Noise Rate | B3: 0.0065 | C3: 0 | D3: 0 | E3: 0 | F3: 0 | G3: 0 | H3: 0.0027 | I3: 0 | J3: 0.0021 | K3: 0.0005 | L3: 0.001 | M3: 0 | N3: 0.0248 | O3: 0.0367 | P3: 0.0302 | Q3: 0.0344 | R3: 0.0175 | S3: 0.0319 | T3: 0.0344 | U3: 0.0423 | V3: 2.47% | W3: 3.48% | X3: 8.22% | Y3: 11.16% | Z3: ='C202'!$B510 -> 5.26% | AA3: ='C202'!$B531 -> 4.74% | AB3: {=INDEX('C202'!$H:$H,6+(COLUMN()-28)*21)} -> 4.15% | AC3: {=INDEX('C202'!$H:$H,6+(COLUMN()-28)*21)} -> 3.47% | AD3: {=INDEX('C202'!$H:$H,6+(COLUMN()-28)*21)} -> 2.43% | AE3: {=INDEX('C202'!$H:$H,6+(COLUMN()-28)*21)} -> 5.85% | AF3: {=INDEX('C202'!$H:$H,6+(COLUMN()-28)*21)} -> 7.44% | AG3: {=INDEX('C202'!$H:$H,6+(COLUMN()-28)*21)} -> 7.84% | AH3: {=INDEX('C202'!$H:$H,6+(COLUMN()-28)*21)} -> 7.42% | AI3: {=INDEX('C202'!$H:$H,6+(COLUMN()-28)*21)} -> 6.58% | ... AY3: {=INDEX('C202'!$H:$H,6+(COLUMN()-28)*21)} -> 9.81% | AZ3: {=_xlfn.NUMBERVALUE(INDEX('C202'!$H:$H,6+(COLUMN()-28)*21))} -> 0.0905 | BA3: {=INDEX('C202'!$H:$H,6+(COLUMN()-28)*21)} -> 10.55% | BB3: {=_xlfn.NUMBERVALUE(INDEX('C202'!$N:$N,6+(COLUMN()-54)*21))} -> 0.0616 | BC3: {=_xlfn.NUMBERVALUE(INDEX('C202'!$N:$N,6+(COLUMN()-54)*21))} -> 0.1189 | BD3: {=_xlfn.NUMBERVALUE(INDEX('C202'!$N:$N,6+(COLUMN()-54)*21))} -> 0.0665 | BE3: {=_xlfn.NUMBERVALUE(INDEX('C202'!$N:$N,6+(COLUMN()-54)*21))} -> 0.1135 | BF3: {=_xlfn.NUMBERVALUE(INDEX('C202'!$N:$N,6+(COLUMN()-54)*21))} -> 0.0311 | BG3: {=_xlfn.NUMBERVALUE(INDEX('C202'!$N:$N,6+(COLUMN()-54)*21))} -> 0.0387 | BH3: {=_xlfn.NUMBERVALUE(INDEX('C202'!$N:$N,6+(COLUMN()-54)*21))} -> 0.0213 | BI3: {=_xlfn.NUMBERVALUE(INDEX('C202'!$N:$N,6+(COLUMN()-54)*21))} -> 0.0493 | ... CA3: {=_xlfn.NUMBERVALUE(INDEX('C202'!$N:$N,6+(COLUMN()-54)*21))} -> 0 | DO3: Noise Fail | DP3: {=INDEX('C202'!$H:$H,9+4*21)+INDEX('C202'!$H:$H,9+5*21)+INDEX('C202'!$H:$H,9+6*21)+INDEX('C202'!$H:$H,9+7*21)+INDEX('C202'!$H:$H,9+8*21)+INDEX('C202'!$H:$H,9+9*21)} -> 1383 | DQ3: {=INDEX('C202'!$H:$H,9+10*21)+INDEX('C202'!$H:$H,9+11*21)+INDEX('C202'!$H:$H,9+12*21)+INDEX('C202'!$H:$H,9+13*21)+INDEX('C202'!$H:$H,9+14*21)+INDEX('C202'!$H:$H,9+15*21)} -> 1539 | DR3: {=INDEX('C202'!$H:$H,9+16*21)+INDEX('C202'!$H:$H,9+17*21)+INDEX('C202'!$H:$H,9+18*21)+INDEX('C202'!$H:$H,9+19*21)+INDEX('C202'!$H:$H,9+20*21)+INDEX('C202'!$H:$H,9+21*21)} -> 1669 | EA3: 設備重啟無確認測試參數 | EB3: 製造一、二課需學習調整duty | EC3: 教材已完成，製造課長學習調整duty | ED3: TBD
A4: RPM Fail Rate | B4: 0.0009 | C4: 0.0038 | D4: 0.0017 | E4: 0.0027 | F4: 0.0049 | G4: 0.0235 | H4: 0.0027 | I4: 0.0039 | J4: 0.0014 | K4: 0.009 | L4: 0.0062 | M4: 0.0037 | N4: 0.0138 | O4: 0.0023 | P4: 0.0091 | Q4: 0.0272 | R4: 0.0205 | S4: 0.0054 | T4: 0.0044 | U4: 0.0052 | V4: 0.62% | W4: 0.07% | X4: 0.57% | Y4: 0.17% | Z4: ='C202'!$B511 -> 0.65% | AA4: ='C202'!$B532 -> 0.32% | AB4: {=INDEX('C202'!$H:$H,7+(COLUMN()-28)*21)} -> 0.28% | AC4: {=INDEX('C202'!$H:$H,7+(COLUMN()-28)*21)} -> 0.41% | AD4: {=INDEX('C202'!$H:$H,7+(COLUMN()-28)*21)} -> 0.22% | AE4: {=INDEX('C202'!$H:$H,7+(COLUMN()-28)*21)} -> 0.37% | AF4: {=INDEX('C202'!$H:$H,7+(COLUMN()-28)*21)} -> 1.08% | AG4: {=INDEX('C202'!$H:$H,7+(COLUMN()-28)*21)} -> 2.71% | AH4: {=INDEX('C202'!$H:$H,7+(COLUMN()-28)*21)} -> 1.07% | AI4: {=INDEX('C202'!$H:$H,7+(COLUMN()-28)*21)} -> 0.61% | ... AY4: {=INDEX('C202'!$H:$H,7+(COLUMN()-28)*21)} -> 0.09% | AZ4: {=_xlfn.NUMBERVALUE(INDEX('C202'!$H:$H,7+(COLUMN()-28)*21))} -> 0.0003 | BA4: {=INDEX('C202'!$H:$H,7+(COLUMN()-28)*21)} -> 0.14% | BB4: {=_xlfn.NUMBERVALUE(INDEX('C202'!$N:$N,7+(COLUMN()-54)*21))} -> 0.0271 | BC4: {=_xlfn.NUMBERVALUE(INDEX('C202'!$N:$N,7+(COLUMN()-54)*21))} -> 0.065 | BD4: {=_xlfn.NUMBERVALUE(INDEX('C202'!$N:$N,7+(COLUMN()-54)*21))} -> 0.0154 | BE4: {=_xlfn.NUMBERVALUE(INDEX('C202'!$N:$N,7+(COLUMN()-54)*21))} -> 0.0124 | BF4: {=_xlfn.NUMBERVALUE(INDEX('C202'!$N:$N,7+(COLUMN()-54)*21))} -> 0.003 | BG4: {=_xlfn.NUMBERVALUE(INDEX('C202'!$N:$N,7+(COLUMN()-54)*21))} -> 0.0423 | BH4: {=_xlfn.NUMBERVALUE(INDEX('C202'!$N:$N,7+(COLUMN()-54)*21))} -> 0.033 | BI4: {=_xlfn.NUMBERVALUE(INDEX('C202'!$N:$N,7+(COLUMN()-54)*21))} -> 0.0311 | ... CA4: {=_xlfn.NUMBERVALUE(INDEX('C202'!$N:$N,7+(COLUMN()-54)*21))} -> 0 | DO4: RPM Fail | DP4: {=INDEX('C202'!$H:$H,15+4*21)+INDEX('C202'!$H:$H,15+5*21)+INDEX('C202'!$H:$H,15+6*21)+INDEX('C202'!$H:$H,15+7*21)+INDEX('C202'!$H:$H,15+8*21)+INDEX('C202'!$H:$H,15+9*21)} -> 197 | DQ4: {=INDEX('C202'!$H:$H,15+10*21)+INDEX('C202'!$H:$H,15+11*21)+INDEX('C202'!$H:$H,15+12*21)+INDEX('C202'!$H:$H,15+13*21)+INDEX('C202'!$H:$H,15+14*21)+INDEX('C202'!$H:$H,15+15*21)} -> 253 | DR4: {=INDEX('C202'!$H:$H,15+16*21)+INDEX('C202'!$H:$H,15+17*21)+INDEX('C202'!$H:$H,15+18*21)+INDEX('C202'!$H:$H,15+19*21)+INDEX('C202'!$H:$H,15+20*21)+INDEX('C202'!$H:$H,15+21*21)} -> 38 | DU4: 2 | DV4: 治具異常 | DW4: 無轉速/失控/無條碼的數量平均分布 | EA4: 治具異常管理 | EB4: 載具ID；測試軟體配置上傳載具ID | EC4: 燒錄設備已完成，201已完成，其餘待展開 | ED4: 46143
A5: Other Fail Rate | B5: 0.0009 | C5: 0 | D5: 0 | E5: 0 | F5: 0 | G5: 0.0006 | H5: 0 | I5: 0 | J5: 0 | K5: 0 | L5: 0.0005 | M5: 0 | N5: 0 | O5: 0 | P5: 0 | Q5: 0 | R5: 0 | S5: 0 | T5: 0 | U5: 0 | V5: 0 | W5: 0.00% | X5: 0.00% | Y5: 1.49% | Z5: ='C202'!$B512 -> 0.12% | AA5: ='C202'!$B533 -> 0.05% | AB5: {=INDEX('C202'!$H:$H,8+(COLUMN()-28)*21)} -> 0.05% | AC5: {=INDEX('C202'!$H:$H,8+(COLUMN()-28)*21)} -> 0.03% | AD5: {=INDEX('C202'!$H:$H,8+(COLUMN()-28)*21)} -> 0.04% | AE5: {=INDEX('C202'!$H:$H,8+(COLUMN()-28)*21)} -> 0.00% | AF5: {=INDEX('C202'!$H:$H,8+(COLUMN()-28)*21)} -> 0.00% | AG5: {=INDEX('C202'!$H:$H,8+(COLUMN()-28)*21)} -> 0.08% | AH5: {=INDEX('C202'!$H:$H,8+(COLUMN()-28)*21)} -> 0.00% | AI5: {=INDEX('C202'!$H:$H,8+(COLUMN()-28)*21)} -> 0.00% | ... AY5: {=INDEX('C202'!$H:$H,8+(COLUMN()-28)*21)} -> 0.00% | AZ5: {=_xlfn.NUMBERVALUE(INDEX('C202'!$H:$H,8+(COLUMN()-28)*21))} -> 0.0003 | BA5: {=INDEX('C202'!$H:$H,8+(COLUMN()-28)*21)} -> 0.03% | BB5: {=_xlfn.NUMBERVALUE(INDEX('C202'!$N:$N,8+(COLUMN()-54)*21))} -> 0 | BC5: {=_xlfn.NUMBERVALUE(INDEX('C202'!$N:$N,8+(COLUMN()-54)*21))} -> 0.0007 | BD5: {=_xlfn.NUMBERVALUE(INDEX('C202'!$N:$N,8+(COLUMN()-54)*21))} -> 0.0004 | BE5: {=_xlfn.NUMBERVALUE(INDEX('C202'!$N:$N,8+(COLUMN()-54)*21))} -> 0.0004 | BF5: {=_xlfn.NUMBERVALUE(INDEX('C202'!$N:$N,8+(COLUMN()-54)*21))} -> 0 | BG5: {=_xlfn.NUMBERVALUE(INDEX('C202'!$N:$N,8+(COLUMN()-54)*21))} -> 0.0075 | BH5: {=_xlfn.NUMBERVALUE(INDEX('C202'!$N:$N,8+(COLUMN()-54)*21))} -> 0 | BI5: {=_xlfn.NUMBERVALUE(INDEX('C202'!$N:$N,8+(COLUMN()-54)*21))} -> 0.0017 | ... CA5: {=_xlfn.NUMBERVALUE(INDEX('C202'!$N:$N,8+(COLUMN()-54)*21))} -> 0 | DO5: Others Fail | DP5: {=INDEX('C202'!$H:$H,18+4*21)+INDEX('C202'!$H:$H,18+5*21)+INDEX('C202'!$H:$H,18+6*21)+INDEX('C202'!$H:$H,18+7*21)+INDEX('C202'!$H:$H,18+8*21)+INDEX('C202'!$H:$H,18+9*21)} -> 4 | DQ5: {=INDEX('C202'!$H:$H,18+10*21)+INDEX('C202'!$H:$H,18+11*21)+INDEX('C202'!$H:$H,18+12*21)+INDEX('C202'!$H:$H,18+13*21)+INDEX('C202'!$H:$H,18+14*21)+INDEX('C202'!$H:$H,18+15*21)} -> 28 | DR5: {=INDEX('C202'!$H:$H,18+16*21)+INDEX('C202'!$H:$H,18+17*21)+INDEX('C202'!$H:$H,18+18*21)+INDEX('C202'!$H:$H,18+19*21)+INDEX('C202'!$H:$H,18+20*21)+INDEX('C202'!$H:$H,18+21*21)} -> 3 | EA5: Fail | EB5: error code上傳至設備(載具、中轉板自動排查) | EC5: 軟體功能未完成 | ED5: 46143
A6: Failure Mode | N6: 1, 4 | O6: 1, 4, 6 | P6: 1, 4, 6 | Q6: 1, 4, 6 | R6: 1, 4 | S6: 1, 4, 6 | T6: 4, 6 | U6: 4, 6 | V6: 4 | W6: 4, 6 | X6: 4, 6 | Y6: 4, 6 | Z6: 4, 6 | BU6: 更換機種沒找TE調參數 | DO6: Tag | DP6: 音頻含有異音 | DQ6: 音頻含有異音 | DR6: 音頻含有異音 | DU6: 3 | DV6: 機構異常 | DW6: 單台機無轉速/無條碼 | EA6: 探針故障 | EB6: 測試軟件增加一D地址，輸出判斷status | EC6: 人機統計功能已完成於C217，未展開 | ED6: 驗證Status後，確認OK後進行
A7: Shut down device | B7: 1 | C7: 2 | D7: 2 | E7: 2 | F7: 2 | G7: 2 | H7: 2 | I7: 2 | J7: 2 | K7: 2 | L7: 2 | M7: 2 | N7: 1 | O7: 1 | P7: 1 | Q7: 1 | R7: 1 | S7: 1 | T7: 1 | U7: 1 | V7: 1 | W7: =COUNTIFS('C202'!$C$444:$H$444,"=0") -> 1 | X7: =COUNTIFS('C202'!$C$465:$H$465,"=0") -> 1 | Y7: =COUNTIFS('C202'!$C$486:$H$486,"=0") -> 1 | Z7: =COUNTIFS('C202'!$C$507:$H$507,"=0") -> 1 | AA7: =COUNTIFS('C202'!$C$528:$H$528,"=0") -> 1 | DQ7: 中轉版故障 | EB7: Status定義已完成，測試軟體待更新 | EC7: Status定義已完成，測試軟體待更新 | ED7: 46142
A8: C203 | B8: 46083 | C8: 46084 | D8: 46085 | E8: 46086 | F8: 46087 | G8: 46088 | H8: 46090 | I8: 46091 | J8: 46092 | K8: 46093 | L8: 46094 | M8: 46095 | N8: 46097 | O8: 46098 | P8: 46099 | Q8: 46100 | R8: 46101 | S8: 46102 | T8: 46104 | U8: 46105 | V8: 46106 | W8: 46107 | X8: 46108 | Y8: 46109 | Z8: 46111 | AA8: 46112 | AB8: 46113 | AC8: 46114 | AD8: 46115 | AE8: 46116 | AF8: 46118 | AG8: 46119 | AH8: 46120 | AI8: 46121 | AJ8: 46122 | AK8: 46123 | AL8: 46125 | AM8: 46126 | AN8: 46127 | AO8: 46128 | AP8: 46129 | AQ8: 46130 | AR8: 46132 | AS8: 46133 | AT8: 46134 | AU8: 46135 | AV8: 46136 | AW8: 46137 | AX8: 46139 | AY8: 46140 | AZ8: 46141 | BA8: 46142 | BB8: 46143 | BC8: 46146 | BD8: 46147 | BE8: 46148 | BF8: 46149 | BG8: 46150 | BH8: 46151 | BI8: 46153 | BJ8: 46154 | BK8: 46155 | BL8: 46156 | BM8: 46157 | BN8: 46158 | BO8: 46160 | BP8: 46161 | BQ8: 46162 | BR8: 46163 | BS8: 46164 | BT8: 46165 | BU8: 46167 | BV8: 46168 | BW8: 46169 | BX8: 46170 | BY8: 46171 | BZ8: 46172 | CA8: 46173 | DO8: C203 | DP8: W15(4/6~11) | DQ8: W16(4/13~18) | DR8: W17(4/20~25) | DU8: 4 | DV8: 音訊部件異常 | DW8: 音頻檔有爆音、dB值較低，或麥克風位置異常 | EA8: 麥克風位置偏移、麥克風/信號線故障、隔音箱內部氣管漏氣 | EB8: 新增異音自檢功能 | EC8: 已完成 | ED8: 46143
A9: Total Fail Rate | G9: 0.0658 | H9: 0.0802 | I9: 0.0858 | J9: 0.0634 | K9: 0.0874 | L9: 0.1028 | M9: 0.1271 | N9: 0.082 | O9: 0.1536 | P9: 0.1185 | Q9: 0.1145 | R9: 0.1347 | S9: 0.0989 | T9: 0.1501 | U9: 0.1248 | V9: 12.05% | W9: 10.59% | X9: 22.63% | Y9: 22.21% | Z9: ='C203'!$B404 -> 20.59% | AA9: ='C203'!$B425 -> 19.90% | AB9: {=INDEX('C203'!$H:$H,5+(COLUMN()-28)*21)} -> 14.66% | AC9: {=INDEX('C203'!$H:$H,5+(COLUMN()-28)*21)} -> 16.22% | AD9: {=INDEX('C203'!$H:$H,5+(COLUMN()-28)*21)} -> 12.97% | AE9: {=INDEX('C203'!$H:$H,5+(COLUMN()-28)*21)} -> 9.14% | AF9: {=INDEX('C203'!$H:$H,5+(COLUMN()-28)*21)} -> 17.39% | AG9: {=INDEX('C203'!$H:$H,5+(COLUMN()-28)*21)} -> 17.50% | AH9: {=INDEX('C203'!$H:$H,5+(COLUMN()-28)*21)} -> 13.24% | AI9: {=INDEX('C203'!$H:$H,5+(COLUMN()-28)*21)} -> 12.62% | ... BA9: {=INDEX('C203'!$H:$H,5+(COLUMN()-28)*21)} -> 11.65% | BB9: {=_xlfn.NUMBERVALUE(INDEX('C203'!$N:$N,5+(COLUMN()-54)*21))} -> 0.0942 | BC9: {=_xlfn.NUMBERVALUE(INDEX('C203'!$N:$N,5+(COLUMN()-54)*21))} -> 0.1121 | BD9: {=_xlfn.NUMBERVALUE(INDEX('C203'!$N:$N,5+(COLUMN()-54)*21))} -> 0.1209 | BE9: {=_xlfn.NUMBERVALUE(INDEX('C203'!$N:$N,5+(COLUMN()-54)*21))} -> 0.1233 | BF9: {=_xlfn.NUMBERVALUE(INDEX('C203'!$N:$N,5+(COLUMN()-54)*21))} -> 0.1471 | BG9: {=_xlfn.NUMBERVALUE(INDEX('C203'!$N:$N,5+(COLUMN()-54)*21))} -> 0.1367 | BH9: {=_xlfn.NUMBERVALUE(INDEX('C203'!$N:$N,5+(COLUMN()-54)*21))} -> 0.0741 | BI9: {=_xlfn.NUMBERVALUE(INDEX('C203'!$N:$N,5+(COLUMN()-54)*21))} -> 0 | ... CA9: {=_xlfn.NUMBERVALUE(INDEX('C203'!$N:$N,5+(COLUMN()-54)*21))} -> 0 | DO9: Total | DP9: {=INDEX('C203'!$H:$H,3+4*21)+INDEX('C203'!$H:$H,3+5*21)+INDEX('C203'!$H:$H,3+6*21)+INDEX('C203'!$H:$H,3+7*21)+INDEX('C203'!$H:$H,3+8*21)+INDEX('C203'!$H:$H,3+9*21)} -> 10296 | DQ9: {=INDEX('C203'!$H:$H,3+10*21)+INDEX('C203'!$H:$H,3+11*21)+INDEX('C203'!$H:$H,3+12*21)+INDEX('C203'!$H:$H,3+13*21)+INDEX('C203'!$H:$H,3+14*21)+INDEX('C203'!$H:$H,3+15*21)} -> 18739 | DR9: {=INDEX('C203'!$H:$H,3+16*21)+INDEX('C203'!$H:$H,3+17*21)+INDEX('C203'!$H:$H,3+18*21)+INDEX('C203'!$H:$H,3+19*21)+INDEX('C203'!$H:$H,3+20*21)+INDEX('C203'!$H:$H,3+21*21)} -> 16747 | EB9: 配置操作說明 | EC9: 已完成
A10: Noise Rate | G10: 0.0466 | H10: 0.0271 | I10: 0.0353 | J10: 0.0386 | K10: 0.0636 | L10: 0.0797 | M10: 0.0961 | N10: 0.0516 | O10: 0.1123 | P10: 0.0818 | Q10: 0.0731 | R10: 0.0716 | S10: 0.0431 | T10: 0.0504 | U10: 0.0635 | V10: 7.58% | W10: 6.01% | X10: 9.23% | Y10: 14.93% | Z10: ='C203'!$B405 -> 16.04% | AA10: ='C203'!$B426 -> 10.87% | AB10: {=INDEX('C203'!$H:$H,6+(COLUMN()-28)*21)} -> 8.85% | AC10: {=INDEX('C203'!$H:$H,6+(COLUMN()-28)*21)} -> 7.01% | AD10: {=INDEX('C203'!$H:$H,6+(COLUMN()-28)*21)} -> 5.83% | AE10: {=INDEX('C203'!$H:$H,6+(COLUMN()-28)*21)} -> 0.00% | AF10: {=INDEX('C203'!$H:$H,6+(COLUMN()-28)*21)} -> 11.37% | AG10: {=INDEX('C203'!$H:$H,6+(COLUMN()-28)*21)} -> 12.22% | AH10: {=INDEX('C203'!$H:$H,6+(COLUMN()-28)*21)} -> 7.79% | AI10: {=INDEX('C203'!$H:$H,6+(COLUMN()-28)*21)} -> 10.08% | ... BA10: {=INDEX('C203'!$H:$H,6+(COLUMN()-28)*21)} -> 8.32% | BB10: {=_xlfn.NUMBERVALUE(INDEX('C203'!$N:$N,6+(COLUMN()-54)*21))} -> 0.0678 | BC10: {=_xlfn.NUMBERVALUE(INDEX('C203'!$N:$N,6+(COLUMN()-54)*21))} -> 0.0605 | BD10: {=_xlfn.NUMBERVALUE(INDEX('C203'!$N:$N,6+(COLUMN()-54)*21))} -> 0.0979 | BE10: {=_xlfn.NUMBERVALUE(INDEX('C203'!$N:$N,6+(COLUMN()-54)*21))} -> 0.1153 | BF10: {=_xlfn.NUMBERVALUE(INDEX('C203'!$N:$N,6+(COLUMN()-54)*21))} -> 0.1269 | BG10: {=_xlfn.NUMBERVALUE(INDEX('C203'!$N:$N,6+(COLUMN()-54)*21))} -> 0.1048 | BH10: {=_xlfn.NUMBERVALUE(INDEX('C203'!$N:$N,6+(COLUMN()-54)*21))} -> 0.0699 | BI10: {=_xlfn.NUMBERVALUE(INDEX('C203'!$N:$N,6+(COLUMN()-54)*21))} -> 0 | ... CA10: {=_xlfn.NUMBERVALUE(INDEX('C203'!$N:$N,6+(COLUMN()-54)*21))} -> 0 | DO10: Noise Fail | DP10: {=INDEX('C203'!$H:$H,9+4*21)+INDEX('C203'!$H:$H,9+5*21)+INDEX('C203'!$H:$H,9+6*21)+INDEX('C203'!$H:$H,9+7*21)+INDEX('C203'!$H:$H,9+8*21)+INDEX('C203'!$H:$H,9+9*21)} -> 1093 | DQ10: {=INDEX('C203'!$H:$H,9+10*21)+INDEX('C203'!$H:$H,9+11*21)+INDEX('C203'!$H:$H,9+12*21)+INDEX('C203'!$H:$H,9+13*21)+INDEX('C203'!$H:$H,9+14*21)+INDEX('C203'!$H:$H,9+15*21)} -> 2059 | DR10: {=INDEX('C203'!$H:$H,9+16*21)+INDEX('C203'!$H:$H,9+17*21)+INDEX('C203'!$H:$H,9+18*21)+INDEX('C203'!$H:$H,9+19*21)+INDEX('C203'!$H:$H,9+20*21)+INDEX('C203'!$H:$H,9+21*21)} -> 1619 | EB10: 平展
A11: RPM Fail Rate | G11: 0.0192 | H11: 0.0531 | I11: 0.0505 | J11: 0.0248 | K11: 0.0238 | L11: 0.0231 | M11: 0.031 | N11: 0.0304 | O11: 0.051 | P11: 0.0434 | Q11: 0.0592 | R11: 0.0643 | S11: 0.0558 | T11: 0.0997 | U11: 0.061 | V11: 4.47% | W11: 4.58% | X11: 13.39% | Y11: 7.20% | Z11: ='C203'!$B406 -> 4.55% | AA11: ='C203'!$B427 -> 9.04% | AB11: {=INDEX('C203'!$H:$H,7+(COLUMN()-28)*21)} -> 5.81% | AC11: {=INDEX('C203'!$H:$H,7+(COLUMN()-28)*21)} -> 9.13% | AD11: {=INDEX('C203'!$H:$H,7+(COLUMN()-28)*21)} -> 7.14% | AE11: {=INDEX('C203'!$H:$H,7+(COLUMN()-28)*21)} -> 8.88% | AF11: {=INDEX('C203'!$H:$H,7+(COLUMN()-28)*21)} -> 6.02% | AG11: {=INDEX('C203'!$H:$H,7+(COLUMN()-28)*21)} -> 5.33% | AH11: {=INDEX('C203'!$H:$H,7+(COLUMN()-28)*21)} -> 5.46% | AI11: {=INDEX('C203'!$H:$H,7+(COLUMN()-28)*21)} -> 2.47% | ... BA11: {=INDEX('C203'!$H:$H,7+(COLUMN()-28)*21)} -> 3.33% | BB11: {=_xlfn.NUMBERVALUE(INDEX('C203'!$N:$N,7+(COLUMN()-54)*21))} -> 0.0264 | BC11: {=_xlfn.NUMBERVALUE(INDEX('C203'!$N:$N,7+(COLUMN()-54)*21))} -> 0.0516 | BD11: {=_xlfn.NUMBERVALUE(INDEX('C203'!$N:$N,7+(COLUMN()-54)*21))} -> 0.0231 | BE11: {=_xlfn.NUMBERVALUE(INDEX('C203'!$N:$N,7+(COLUMN()-54)*21))} -> 0.008 | BF11: {=_xlfn.NUMBERVALUE(INDEX('C203'!$N:$N,7+(COLUMN()-54)*21))} -> 0.0202 | BG11: {=_xlfn.NUMBERVALUE(INDEX('C203'!$N:$N,7+(COLUMN()-54)*21))} -> 0.0318 | BH11: {=_xlfn.NUMBERVALUE(INDEX('C203'!$N:$N,7+(COLUMN()-54)*21))} -> 0.0042 | BI11: {=_xlfn.NUMBERVALUE(INDEX('C203'!$N:$N,7+(COLUMN()-54)*21))} -> 0 | ... CA11: {=_xlfn.NUMBERVALUE(INDEX('C203'!$N:$N,7+(COLUMN()-54)*21))} -> 0 | DO11: RPM Fail | DP11: {=INDEX('C203'!$H:$H,15+4*21)+INDEX('C203'!$H:$H,15+5*21)+INDEX('C203'!$H:$H,15+6*21)+INDEX('C203'!$H:$H,15+7*21)+INDEX('C203'!$H:$H,15+8*21)+INDEX('C203'!$H:$H,15+9*21)} -> 431 | DQ11: {=INDEX('C203'!$H:$H,15+10*21)+INDEX('C203'!$H:$H,15+11*21)+INDEX('C203'!$H:$H,15+12*21)+INDEX('C203'!$H:$H,15+13*21)+INDEX('C203'!$H:$H,15+14*21)+INDEX('C203'!$H:$H,15+15*21)} -> 971 | DR11: {=INDEX('C203'!$H:$H,15+16*21)+INDEX('C203'!$H:$H,15+17*21)+INDEX('C203'!$H:$H,15+18*21)+INDEX('C203'!$H:$H,15+19*21)+INDEX('C203'!$H:$H,15+20*21)+INDEX('C203'!$H:$H,15+21*21)} -> 441 | DU11: 5 | DV11: 測試參數定義錯誤 | DW11: 未達到合適的轉速、index | EA11: 新機種未確認工作duty | EB11: 測試程序調用要求加入OI中
A12: Other Fail Rate | G12: 0 | H12: 0 | I12: 0.001 | J12: 0.0007 | K12: 0.0016 | L12: 0.0009 | M12: 0.0021 | N12: 0.0174 | O12: 0.0109 | P12: 0.0008 | Q12: 0 | R12: 0 | S12: 0 | T12: 0 | U12: 0.001 | V12: 0.25% | W12: 0.07% | X12: 9.08% | Y12: 0.08% | Z12: ='C203'!$B407 -> 0.00% | AA12: ='C203'!$B428 -> 0.00% | AB12: {=INDEX('C203'!$H:$H,8+(COLUMN()-28)*21)} -> 0.00% | AC12: {=INDEX('C203'!$H:$H,8+(COLUMN()-28)*21)} -> 0.00% | AD12: {=INDEX('C203'!$H:$H,8+(COLUMN()-28)*21)} -> 0.00% | AE12: {=INDEX('C203'!$H:$H,8+(COLUMN()-28)*21)} -> 0.00% | AF12: {=INDEX('C203'!$H:$H,8+(COLUMN()-28)*21)} -> 0.00% | AG12: {=INDEX('C203'!$H:$H,8+(COLUMN()-28)*21)} -> 0.00% | AH12: {=INDEX('C203'!$H:$H,8+(COLUMN()-28)*21)} -> 0.16% | AI12: {=INDEX('C203'!$H:$H,8+(COLUMN()-28)*21)} -> 0.00% | ... BA12: {=INDEX('C203'!$H:$H,8+(COLUMN()-28)*21)} -> 0.32% | BB12: {=_xlfn.NUMBERVALUE(INDEX('C203'!$N:$N,8+(COLUMN()-54)*21))} -> 0.0013 | BC12: {=_xlfn.NUMBERVALUE(INDEX('C203'!$N:$N,8+(COLUMN()-54)*21))} -> 0.028 | BD12: {=_xlfn.NUMBERVALUE(INDEX('C203'!$N:$N,8+(COLUMN()-54)*21))} -> 0 | BE12: {=_xlfn.NUMBERVALUE(INDEX('C203'!$N:$N,8+(COLUMN()-54)*21))} -> 0.0016 | BF12: {=_xlfn.NUMBERVALUE(INDEX('C203'!$N:$N,8+(COLUMN()-54)*21))} -> 0.0011 | BG12: {=_xlfn.NUMBERVALUE(INDEX('C203'!$N:$N,8+(COLUMN()-54)*21))} -> 0.0011 | BH12: {=_xlfn.NUMBERVALUE(INDEX('C203'!$N:$N,8+(COLUMN()-54)*21))} -> 0.0009 | BI12: {=_xlfn.NUMBERVALUE(INDEX('C203'!$N:$N,8+(COLUMN()-54)*21))} -> 0 | ... CA12: {=_xlfn.NUMBERVALUE(INDEX('C203'!$N:$N,8+(COLUMN()-54)*21))} -> 0 | DO12: Others Fail | DP12: {=INDEX('C203'!$H:$H,18+4*21)+INDEX('C203'!$H:$H,18+5*21)+INDEX('C203'!$H:$H,18+6*21)+INDEX('C203'!$H:$H,18+7*21)+INDEX('C203'!$H:$H,18+8*21)+INDEX('C203'!$H:$H,18+9*21)} -> 4 | DQ12: {=INDEX('C203'!$H:$H,18+10*21)+INDEX('C203'!$H:$H,18+11*21)+INDEX('C203'!$H:$H,18+12*21)+INDEX('C203'!$H:$H,18+13*21)+INDEX('C203'!$H:$H,18+14*21)+INDEX('C203'!$H:$H,18+15*21)} -> 64 | DR12: {=INDEX('C203'!$H:$H,18+16*21)+INDEX('C203'!$H:$H,18+17*21)+INDEX('C203'!$H:$H,18+18*21)+INDEX('C203'!$H:$H,18+19*21)+INDEX('C203'!$H:$H,18+20*21)+INDEX('C203'!$H:$H,18+21*21)} -> 25 | EB12: 測試程序雲端化
A13: Failure Mode | G13: 1, 4, 5, 6 | H13: 1, 2, 4, 5, 6 | I13: 1, 2, 4, 5, 6 | J13: 1, 2, 4, 5, 6 | K13: 1, 2, 4, 5, 6 | L13: 1, 2, 5, 4, 6 | M13: 1, 2, 5, 4, 6 | N13: 1, 2, 3, 5, 4, 6 | O13: 1, 2, 3, 4, 6 | P13: 1, 2, 4, 6 | Q13: 1, 2, 4, 6 | R13: 1, 2, 4, 5, 6 | S13: 2, 4, 6 | T13: 2, 4, 6 | U13: 2, 4, 6 | V13: 2, 4, 6 | W13: 2, 4, 6 | X13: 2, 4, 6, 網路 | Y13: 2, 4, 6, OK but NGX | Z13: 2, 6, OK but NGX | DO13: Tag | DP13: 音頻含有異音 | DQ13: 音頻含有異音 | DR13: 音頻含有異音 | DU13: 6 | DV13: 異音不良 | DW13: 音頻包含異響 | EA13: 測試軟件與人耳判定結果不同、風扇運轉不穩定導致異響偶發
A14: Shut down device | G14: =COUNTIFS('C203'!$C$3:$F$3,"=0") -> 0 | H14: =COUNTIFS('C203'!$C$24:$F$24,"=0") -> 0 | I14: =COUNTIFS('C203'!$C$45:$F$45,"=0") -> 0 | J14: =COUNTIFS('C203'!$C$66:$F$66,"=0") -> 0 | K14: =COUNTIFS('C203'!$C$87:$F$87,"=0") -> 0 | L14: =COUNTIFS('C203'!$C$108:$F$108,"=0") -> 0 | M14: =COUNTIFS('C203'!$C$129:$F$129,"=0") -> 0 | N14: =COUNTIFS('C203'!$C$150:$F$150,"=0") -> 0 | O14: =COUNTIFS('C203'!$C$171:$F$171,"=0") -> 0 | P14: =COUNTIFS('C203'!$C$192:$F$192,"=0") -> 0 | Q14: =COUNTIFS('C203'!$C$213:$F$213,"=0") -> 0 | R14: =COUNTIFS('C203'!$C$234:$F$234,"=0") -> 0 | S14: =COUNTIFS('C203'!$C$255:$F$255,"=0") -> 0 | T14: =COUNTIFS('C203'!$C$276:$F$276,"=0") -> 0 | U14: =COUNTIFS('C203'!$C$297:$F$297,"=0") -> 0 | V14: =COUNTIFS('C203'!$C$318:$F$318,"=0") -> 0 | W14: =COUNTIFS('C203'!$C$339:$F$339,"=0") -> 0 | X14: =COUNTIFS('C203'!$C$360:$F$360,"=0") -> 0 | Y14: =COUNTIFS('C203'!$C$381:$F$381,"=0") -> 0 | Z14: =COUNTIFS('C203'!$C$402:$F$402,"=0") -> 0 | AA14: =COUNTIFS('C203'!$D$423:$G$423,"=0") -> 0 | DP14: 中轉版故障 | DQ14: 中轉版故障 | DR14: 中轉版故障
A15: C208 | B15: 46083 | C15: 46084 | D15: 46085 | E15: 46086 | F15: 46087 | G15: 46088 | H15: 46090 | I15: 46091 | J15: 46092 | K15: 46093 | L15: 46094 | M15: 46095 | N15: 46097 | O15: 46098 | P15: 46099 | Q15: 46100 | R15: 46101 | S15: 46102 | T15: 46104 | U15: 46105 | V15: 46106 | W15: 46107 | X15: 46108 | Y15: 46109 | Z15: 46111 | AA15: 46112 | AB15: 46113 | AC15: 46114 | AD15: 46115 | AE15: 46116 | AF15: 46118 | AG15: 46119 | AH15: 46120 | AI15: 46121 | AJ15: 46122 | AK15: 46123 | AL15: 46125 | AM15: 46126 | AN15: 46127 | AO15: 46128 | AP15: 46129 | AQ15: 46130 | AR15: 46132 | AS15: 46133 | AT15: 46134 | AU15: 46135 | AV15: 46136 | AW15: 46137 | AX15: 46139 | AY15: 46140 | AZ15: 46141 | BA15: 46142 | BB15: 46143 | BC15: 46146 | BD15: 46147 | BE15: 46148 | BF15: 46149 | BG15: 46150 | BH15: 46151 | BI15: 46153 | BJ15: 46154 | BK15: 46155 | BL15: 46156 | BM15: 46157 | BN15: 46158 | BO15: 46160 | BP15: 46161 | BQ15: 46162 | BR15: 46163 | BS15: 46164 | BT15: 46165 | BU15: 46167 | BV15: 46168 | BW15: 46169 | BX15: 46170 | BY15: 46171 | BZ15: 46172 | CA15: 46173 | DO15: C208 | DP15: W15(4/6~11) | DQ15: W16(4/13~18) | DR15: W17(4/20~25)
A16: Total Fail Rate | B16: 0.0089 | C16: 0.0063 | D16: 0.0179 | K16: 0.0237 | L16: 0.0192 | M16: 0.0541 | N16: 0.0064 | O16: 0.0194 | P16: 0.0335 | Q16: 0.0338 | R16: 0.0825 | S16: 0.0948 | T16: 0.0418 | U16: 0.1225 | V16: 5.21% | W16: ='C208'!$B320 -> 12.59% | X16: 1.63% | Y16: 1.96% | Z16: ='C208'!$B383 -> 0.22% | AA16: ='C208'!$B404 -> 2.26% | AB16: {=INDEX('C208'!$I:$I,5+(COLUMN()-28)*21)} -> 0.048676171 | AC16: {=INDEX('C208'!$I:$I,5+(COLUMN()-28)*21)} -> 6.78% | AD16: {=INDEX('C208'!$I:$I,5+(COLUMN()-28)*21)} -> 0.048379175 | AE16: {=INDEX('C208'!$I:$I,5+(COLUMN()-28)*21)} -> 0.1057572 | AF16: {=INDEX('C208'!$I:$I,5+(COLUMN()-28)*21)} -> 0.023285899 | AG16: {=INDEX('C208'!$I:$I,5+(COLUMN()-28)*21)} -> 0.0048129512 | AH16: {=INDEX('C208'!$I:$I,5+(COLUMN()-28)*21)} -> 0.011432927 | AI16: {=INDEX('C208'!$I:$I,5+(COLUMN()-28)*21)} -> 0.0085279188 | ... BA16: {=INDEX('C208'!$I:$I,5+(COLUMN()-28)*21)} -> 0.10979107 | BB16: {=_xlfn.NUMBERVALUE(INDEX('C208'!$P:$P,5+(COLUMN()-54)*21))} -> 0.0177 | BC16: {=_xlfn.NUMBERVALUE(INDEX('C208'!$P:$P,5+(COLUMN()-54)*21))} -> 0.010356732 | BD16: {=_xlfn.NUMBERVALUE(INDEX('C208'!$P:$P,5+(COLUMN()-54)*21))} -> 0.0635 | BE16: {=_xlfn.NUMBERVALUE(INDEX('C208'!$P:$P,5+(COLUMN()-54)*21))} -> 0.0523 | BF16: {=_xlfn.NUMBERVALUE(INDEX('C208'!$P:$P,5+(COLUMN()-54)*21))} -> 0.0118 | BG16: {=_xlfn.NUMBERVALUE(INDEX('C208'!$P:$P,5+(COLUMN()-54)*21))} -> 0.0091 | BH16: {=_xlfn.NUMBERVALUE(INDEX('C208'!$P:$P,5+(COLUMN()-54)*21))} -> 0.0083 | BI16: {=_xlfn.NUMBERVALUE(INDEX('C208'!$P:$P,5+(COLUMN()-54)*21))} -> 0.0114 | ... CA16: {=_xlfn.NUMBERVALUE(INDEX('C208'!$P:$P,5+(COLUMN()-54)*21))} -> 0 | DO16: Total | DP16: {=INDEX('C208'!$I:$I,3+4*21)+INDEX('C208'!$I:$I,3+5*21)+INDEX('C208'!$I:$I,3+6*21)+INDEX('C208'!$I:$I,3+7*21)+INDEX('C208'!$I:$I,3+8*21)+INDEX('C208'!$I:$I,3+9*21)} -> 27415 | DQ16: {=INDEX('C208'!$I:$I,3+10*21)+INDEX('C208'!$I:$I,3+11*21)+INDEX('C208'!$I:$I,3+12*21)+INDEX('C208'!$I:$I,3+13*21)+INDEX('C208'!$I:$I,3+14*21)+INDEX('C208'!$I:$I,3+15*21)} -> 25655 | DR16: {=INDEX('C208'!$I:$I,3+16*21)+INDEX('C208'!$I:$I,3+17*21)+INDEX('C208'!$I:$I,3+18*21)+INDEX('C208'!$I:$I,3+19*21)+INDEX('C208'!$I:$I,3+20*21)+INDEX('C208'!$I:$I,3+21*21)} -> 22603
A17: Noise Rate | B17: 0.0062 | C17: 0.0047 | D17: 0.0179 | K17: 0.0104 | L17: 0.0129 | M17: 0.0505 | N17: 0.0045 | O17: 0.0147 | P17: 0.0296 | Q17: 0.028 | R17: 0.0652 | S17: 0.0586 | T17: 0.0093 | U17: 0.0056 | V17: 0.80% | W17: ='C208'!$B321 -> 0.21% | X17: 0.41% | Y17: 0.49% | Z17: ='C208'!$B384 -> 0.11% | AA17: ='C208'!$B405 -> 1.95% | AB17: {=INDEX('C208'!$I:$I,6+(COLUMN()-28)*21)} -> 0.026476578 | AC17: {=INDEX('C208'!$I:$I,6+(COLUMN()-28)*21)} -> 2.59% | AD17: {=INDEX('C208'!$I:$I,6+(COLUMN()-28)*21)} -> 0.012770138 | AE17: {=INDEX('C208'!$I:$I,6+(COLUMN()-28)*21)} -> 0.049436796 | AF17: {=INDEX('C208'!$I:$I,6+(COLUMN()-28)*21)} -> 0.0090556274 | AG17: {=INDEX('C208'!$I:$I,6+(COLUMN()-28)*21)} -> 0.0024064756 | AH17: {=INDEX('C208'!$I:$I,6+(COLUMN()-28)*21)} -> 0.0051448171 | AI17: {=INDEX('C208'!$I:$I,6+(COLUMN()-28)*21)} -> 0.0050761421 | ... BA17: {=INDEX('C208'!$I:$I,6+(COLUMN()-28)*21)} -> 0.10589922 | BB17: {=_xlfn.NUMBERVALUE(INDEX('C208'!$P:$P,6+(COLUMN()-54)*21))} -> 0.0143 | BC17: {=_xlfn.NUMBERVALUE(INDEX('C208'!$P:$P,6+(COLUMN()-54)*21))} -> 0.0092059839 | BD17: {=_xlfn.NUMBERVALUE(INDEX('C208'!$P:$P,6+(COLUMN()-54)*21))} -> 0.0597 | BE17: {=_xlfn.NUMBERVALUE(INDEX('C208'!$P:$P,6+(COLUMN()-54)*21))} -> 0.0504 | BF17: {=_xlfn.NUMBERVALUE(INDEX('C208'!$P:$P,6+(COLUMN()-54)*21))} -> 0.0113 | BG17: {=_xlfn.NUMBERVALUE(INDEX('C208'!$P:$P,6+(COLUMN()-54)*21))} -> 0.0058 | BH17: {=_xlfn.NUMBERVALUE(INDEX('C208'!$P:$P,6+(COLUMN()-54)*21))} -> 0.0049 | BI17: {=_xlfn.NUMBERVALUE(INDEX('C208'!$P:$P,6+(COLUMN()-54)*21))} -> 0.01 | ... CA17: {=_xlfn.NUMBERVALUE(INDEX('C208'!$P:$P,6+(COLUMN()-54)*21))} -> 0 | DO17: Noise Fail | DP17: {=INDEX('C208'!$I:$I,9+4*21)+INDEX('C208'!$I:$I,9+5*21)+INDEX('C208'!$I:$I,9+6*21)+INDEX('C208'!$I:$I,9+7*21)+INDEX('C208'!$I:$I,9+8*21)+INDEX('C208'!$I:$I,9+9*21)} -> 137 | DQ17: {=INDEX('C208'!$I:$I,9+10*21)+INDEX('C208'!$I:$I,9+11*21)+INDEX('C208'!$I:$I,9+12*21)+INDEX('C208'!$I:$I,9+13*21)+INDEX('C208'!$I:$I,9+14*21)+INDEX('C208'!$I:$I,9+15*21)} -> 287 | DR17: {=INDEX('C208'!$I:$I,9+16*21)+INDEX('C208'!$I:$I,9+17*21)+INDEX('C208'!$I:$I,9+18*21)+INDEX('C208'!$I:$I,9+19*21)+INDEX('C208'!$I:$I,9+20*21)+INDEX('C208'!$I:$I,9+21*21)} -> 1836
A18: RPM Fail Rate | B18: 0.0027 | C18: 0.0016 | D18: 0 | K18: 0.0133 | L18: 0.0062 | M18: 0.0036 | N18: 0.0019 | O18: 0.0048 | P18: 0.0039 | Q18: 0.0058 | R18: 0.0173 | S18: 0.0362 | T18: 0.0322 | U18: 0.1162 | V18: 4.34% | W18: ='C208'!$B322 -> 11.59% | X18: 1.22% | Y18: 1.48% | Z18: ='C208'!$B385 -> 0.11% | AA18: ='C208'!$B406 -> 0.31% | AB18: {=INDEX('C208'!$I:$I,7+(COLUMN()-28)*21)} -> 0.021384929 | AC18: {=INDEX('C208'!$I:$I,7+(COLUMN()-28)*21)} -> 4.17% | AD18: {=INDEX('C208'!$I:$I,7+(COLUMN()-28)*21)} -> 0.035117878 | AE18: {=INDEX('C208'!$I:$I,7+(COLUMN()-28)*21)} -> 0.056320401 | AF18: {=INDEX('C208'!$I:$I,7+(COLUMN()-28)*21)} -> 0.013367831 | AG18: {=INDEX('C208'!$I:$I,7+(COLUMN()-28)*21)} -> 0.0024064756 | AH18: {=INDEX('C208'!$I:$I,7+(COLUMN()-28)*21)} -> 0.006097561 | AI18: {=INDEX('C208'!$I:$I,7+(COLUMN()-28)*21)} -> 0.0028426396 | ... BA18: {=INDEX('C208'!$I:$I,7+(COLUMN()-28)*21)} -> 0.0036870135 | BB18: {=_xlfn.NUMBERVALUE(INDEX('C208'!$P:$P,7+(COLUMN()-54)*21))} -> 0.0034 | BC18: {=_xlfn.NUMBERVALUE(INDEX('C208'!$P:$P,7+(COLUMN()-54)*21))} -> 0.00076716532 | BD18: {=_xlfn.NUMBERVALUE(INDEX('C208'!$P:$P,7+(COLUMN()-54)*21))} -> 0.0039 | BE18: {=_xlfn.NUMBERVALUE(INDEX('C208'!$P:$P,7+(COLUMN()-54)*21))} -> 0.0019 | BF18: {=_xlfn.NUMBERVALUE(INDEX('C208'!$P:$P,7+(COLUMN()-54)*21))} -> 0.0005 | BG18: {=_xlfn.NUMBERVALUE(INDEX('C208'!$P:$P,7+(COLUMN()-54)*21))} -> 0.0033 | BH18: {=_xlfn.NUMBERVALUE(INDEX('C208'!$P:$P,7+(COLUMN()-54)*21))} -> 0.0033 | BI18: {=_xlfn.NUMBERVALUE(INDEX('C208'!$P:$P,7+(COLUMN()-54)*21))} -> 0.0014 | ... CA18: {=_xlfn.NUMBERVALUE(INDEX('C208'!$P:$P,7+(COLUMN()-54)*21))} -> 0 | DO18: RPM Fail | DP18: {=INDEX('C208'!$I:$I,15+4*21)+INDEX('C208'!$I:$I,15+5*21)+INDEX('C208'!$I:$I,15+6*21)+INDEX('C208'!$I:$I,15+7*21)+INDEX('C208'!$I:$I,15+8*21)+INDEX('C208'!$I:$I,15+9*21)} -> 135 | DQ18: {=INDEX('C208'!$I:$I,15+10*21)+INDEX('C208'!$I:$I,15+11*21)+INDEX('C208'!$I:$I,15+12*21)+INDEX('C208'!$I:$I,15+13*21)+INDEX('C208'!$I:$I,15+14*21)+INDEX('C208'!$I:$I,15+15*21)} -> 47 | DR18: {=INDEX('C208'!$I:$I,15+16*21)+INDEX('C208'!$I:$I,15+17*21)+INDEX('C208'!$I:$I,15+18*21)+INDEX('C208'!$I:$I,15+19*21)+INDEX('C208'!$I:$I,15+20*21)+INDEX('C208'!$I:$I,15+21*21)} -> 652
A19: Other Fail Rate | B19: 0.0009 | C19: 0.0005 | D19: 0 | K19: 0.0002 | L19: 0.0019 | M19: 0.0052 | N19: 0.0064 | O19: 0.0069 | P19: 0.0088 | Q19: 0.0023 | R19: 0 | S19: 0.0005 | T19: 0.0011 | U19: 0.0006 | V19: 0.00% | W19: ='C208'!$B323 -> 0.00% | X19: 0.00% | Y19: 0.00% | Z19: ='C208'!$B386 -> 0.00% | AA19: ='C208'!$B407 -> 0.00% | AB19: {=INDEX('C208'!$I:$I,8+(COLUMN()-28)*21)} -> 0.00% | AC19: {=INDEX('C208'!$I:$I,8+(COLUMN()-28)*21)} -> 0.00% | AD19: {=INDEX('C208'!$I:$I,8+(COLUMN()-28)*21)} -> 0.00% | AE19: {=INDEX('C208'!$I:$I,8+(COLUMN()-28)*21)} -> 0.00% | AF19: {=INDEX('C208'!$I:$I,8+(COLUMN()-28)*21)} -> 0.00% | AG19: {=INDEX('C208'!$I:$I,8+(COLUMN()-28)*21)} -> 0.03% | AH19: {=INDEX('C208'!$I:$I,8+(COLUMN()-28)*21)} -> 0.00019054878 | AI19: {=INDEX('C208'!$I:$I,8+(COLUMN()-28)*21)} -> 0.00% | ... BA19: {=INDEX('C208'!$I:$I,8+(COLUMN()-28)*21)} -> 0.00020483408 | BB19: {=_xlfn.NUMBERVALUE(INDEX('C208'!$P:$P,8+(COLUMN()-54)*21))} -> 0 | BC19: {=_xlfn.NUMBERVALUE(INDEX('C208'!$P:$P,8+(COLUMN()-54)*21))} -> 0.001150748 | BD19: {=_xlfn.NUMBERVALUE(INDEX('C208'!$P:$P,8+(COLUMN()-54)*21))} -> 0.0006 | BE19: {=_xlfn.NUMBERVALUE(INDEX('C208'!$P:$P,8+(COLUMN()-54)*21))} -> 0.0005 | BF19: {=_xlfn.NUMBERVALUE(INDEX('C208'!$P:$P,8+(COLUMN()-54)*21))} -> 0 | BG19: {=_xlfn.NUMBERVALUE(INDEX('C208'!$P:$P,8+(COLUMN()-54)*21))} -> 0.0007 | BH19: {=_xlfn.NUMBERVALUE(INDEX('C208'!$P:$P,8+(COLUMN()-54)*21))} -> 0 | BI19: {=_xlfn.NUMBERVALUE(INDEX('C208'!$P:$P,8+(COLUMN()-54)*21))} -> 0.0007 | ... CA19: {=_xlfn.NUMBERVALUE(INDEX('C208'!$P:$P,8+(COLUMN()-54)*21))} -> 0 | DO19: Others Fail | DP19: {=INDEX('C208'!$I:$I,18+4*21)+INDEX('C208'!$I:$I,18+5*21)+INDEX('C208'!$I:$I,18+6*21)+INDEX('C208'!$I:$I,18+7*21)+INDEX('C208'!$I:$I,18+8*21)+INDEX('C208'!$I:$I,18+9*21)} -> 9 | DQ19: {=INDEX('C208'!$I:$I,18+10*21)+INDEX('C208'!$I:$I,18+11*21)+INDEX('C208'!$I:$I,18+12*21)+INDEX('C208'!$I:$I,18+13*21)+INDEX('C208'!$I:$I,18+14*21)+INDEX('C208'!$I:$I,18+15*21)} -> 46 | DR19: {=INDEX('C208'!$I:$I,18+16*21)+INDEX('C208'!$I:$I,18+17*21)+INDEX('C208'!$I:$I,18+18*21)+INDEX('C208'!$I:$I,18+19*21)+INDEX('C208'!$I:$I,18+20*21)+INDEX('C208'!$I:$I,18+21*21)} -> 15
A20: Failure Mode | M20: 4, 6 | O20: 4 | P20: 4 | Q20: 4 | R20: 4, 6 | S20: 4, 6 | T20: 2, 4 | U20: 2, 4 | V20: 2, 4 | W20: 4 | X20: 4 | Y20: 4 | Z20: 4 | DO20: Tag | DR20: 中轉版故障
A21: Shut down device | B21: =COUNTIFS('C208'!$C$3:$F$3,"=0") -> 3 | C21: =COUNTIFS('C208'!$C$24:$F$24,"=0") -> 1 | D21: =COUNTIFS('C208'!$C$45:$F$45,"=0") -> 1 | K21: =COUNTIFS('C208'!$C$66:$F$66,"=0") -> 0 | L21: =COUNTIFS('C208'!$C$87:$F$87,"=0") -> 0 | M21: =COUNTIFS('C208'!$C$108:$F$108,"=0") -> 0 | N21: =COUNTIFS('C208'!$C$129:$F$129,"=0") -> 0 | O21: =COUNTIFS('C208'!$C$150:$F$150,"=0") -> 0 | P21: =COUNTIFS('C208'!$C$171:$F$171,"=0") -> 0 | Q21: =COUNTIFS('C208'!$C$192:$F$192,"=0") -> 0 | R21: =COUNTIFS('C208'!$C$213:$F$213,"=0") -> 0 | S21: =COUNTIFS('C208'!$C$234:$F$234,"=0") -> 0 | T21: =COUNTIFS('C208'!$C$255:$F$255,"=0") -> 1 | U21: =COUNTIFS('C208'!$C$276:$F$276,"=0") -> 0 | V21: =COUNTIFS('C208'!$C$297:$F$297,"=0") -> 0 | W21: =COUNTIFS('C208'!$C$318:$F$318,"=0") -> 0 | X21: =COUNTIFS('C208'!$C$339:$F$339,"=0") -> 0 | Y21: =COUNTIFS('C208'!$C$360:$F$360,"=0") -> 0 | Z21: =COUNTIFS('C208'!$C$381:$G$381,"=0") -> 1 | AA21: =COUNTIFS('C208'!$C$402:$G$402,"=0") -> 0
A22: C209 | B22: 46083 | C22: 46084 | D22: 46085 | E22: 46086 | F22: 46087 | G22: 46088 | H22: 46090 | I22: 46091 | J22: 46092 | K22: 46093 | L22: 46094 | M22: 46095 | N22: 46097 | O22: 46098 | P22: 46099 | Q22: 46100 | R22: 46101 | S22: 46102 | T22: 46104 | U22: 46105 | V22: 46106 | W22: 46107 | X22: 46108 | Y22: 46109 | Z22: 46111 | AA22: 46112 | AB22: 46113 | AC22: 46114 | AD22: 46115 | AE22: 46116 | AF22: 46118 | AG22: 46119 | AH22: 46120 | AI22: 46121 | AJ22: 46122 | AK22: 46123 | AL22: 46125 | AM22: 46126 | AN22: 46127 | AO22: 46128 | AP22: 46129 | AQ22: 46130 | AR22: 46132 | AS22: 46133 | AT22: 46134 | AU22: 46135 | AV22: 46136 | AW22: 46137 | AX22: 46139 | AY22: 46140 | AZ22: 46141 | BA22: 46142 | BB22: 46143 | BC22: 46146 | BD22: 46147 | BE22: 46148 | BF22: 46149 | BG22: 46150 | BH22: 46151 | BI22: 46153 | BJ22: 46154 | BK22: 46155 | BL22: 46156 | BM22: 46157 | BN22: 46158 | BO22: 46160 | BP22: 46161 | BQ22: 46162 | BR22: 46163 | BS22: 46164 | BT22: 46165 | BU22: 46167 | BV22: 46168 | BW22: 46169 | BX22: 46170 | BY22: 46171 | BZ22: 46172 | CA22: 46173 | DO22: C209 | DP22: W15(4/6~11) | DQ22: W16(4/13~18) | DR22: W17(4/20~25)
A23: Total Fail Rate | B23: 0.0837 | C23: 0.1206 | D23: 0.0696 | E23: 0.0801 | F23: 0.0661 | G23: 0.074 | H23: 0.1073 | K23: 0.0837 | L23: 0.0736 | M23: 0.0874 | N23: 0.0928 | O23: 0.1199 | P23: 0.1398 | Q23: 0.1009 | R23: 0.0827 | S23: 0.0838 | T23: 0.0744 | U23: 0.0821 | V23: 10.63% | W23: ='C209'!$B404 -> 7.57% | X23: 8.27% | Y23: 7.43% | Z23: ='C209'!$B467 -> 9.03% | AA23: ='C209'!$B488 -> 6.48% | AB23: {=INDEX('C209'!$I:$I,5+(COLUMN()-28)*21)} -> 9.12% | AC23: {=INDEX('C209'!$I:$I,5+(COLUMN()-28)*21)} -> 7.84% | AD23: {=INDEX('C209'!$I:$I,5+(COLUMN()-28)*21)} -> 0.060842434 | AE23: {=INDEX('C209'!$I:$I,5+(COLUMN()-28)*21)} -> 0.062933514 | AF23: {=INDEX('C209'!$I:$I,5+(COLUMN()-28)*21)} -> 9.80% | AG23: {=INDEX('C209'!$I:$I,5+(COLUMN()-28)*21)} -> 10.72% | AH23: {=INDEX('C209'!$I:$I,5+(COLUMN()-28)*21)} -> 6.45% | AI23: {=INDEX('C209'!$I:$I,5+(COLUMN()-28)*21)} -> 7.46% | ... BA23: {=INDEX('C209'!$I:$I,5+(COLUMN()-28)*21)} -> 2.34% | BB23: {=_xlfn.NUMBERVALUE(INDEX('C209'!$P:$P,5+(COLUMN()-54)*21))} -> 0.0407 | BC23: {=_xlfn.NUMBERVALUE(INDEX('C209'!$P:$P,5+(COLUMN()-54)*21))} -> 0.0509 | BD23: {=_xlfn.NUMBERVALUE(INDEX('C209'!$P:$P,5+(COLUMN()-54)*21))} -> 0.0634 | BE23: {=_xlfn.NUMBERVALUE(INDEX('C209'!$P:$P,5+(COLUMN()-54)*21))} -> 0.0801 | BF23: {=_xlfn.NUMBERVALUE(INDEX('C209'!$P:$P,5+(COLUMN()-54)*21))} -> 0.0683 | BG23: {=_xlfn.NUMBERVALUE(INDEX('C209'!$P:$P,5+(COLUMN()-54)*21))} -> 0.0395 | BH23: {=_xlfn.NUMBERVALUE(INDEX('C209'!$P:$P,5+(COLUMN()-54)*21))} -> 0.0691 | BI23: {=_xlfn.NUMBERVALUE(INDEX('C209'!$P:$P,5+(COLUMN()-54)*21))} -> 0.0572 | ... CA23: {=_xlfn.NUMBERVALUE(INDEX('C209'!$P:$P,5+(COLUMN()-54)*21))} -> 0 | DO23: Total | DP23: {=INDEX('C209'!$I:$I,3+4*21)+INDEX('C209'!$I:$I,3+5*21)+INDEX('C209'!$I:$I,3+6*21)+INDEX('C209'!$I:$I,3+7*21)+INDEX('C209'!$I:$I,3+8*21)+INDEX('C209'!$I:$I,3+9*21)} -> 29047 | DQ23: {=INDEX('C209'!$I:$I,3+10*21)+INDEX('C209'!$I:$I,3+11*21)+INDEX('C209'!$I:$I,3+12*21)+INDEX('C209'!$I:$I,3+13*21)+INDEX('C209'!$I:$I,3+14*21)+INDEX('C209'!$I:$I,3+15*21)} -> 35013 | DR23: {=INDEX('C209'!$I:$I,3+16*21)+INDEX('C209'!$I:$I,3+17*21)+INDEX('C209'!$I:$I,3+18*21)+INDEX('C209'!$I:$I,3+19*21)+INDEX('C209'!$I:$I,3+20*21)+INDEX('C209'!$I:$I,3+21*21)} -> 31499
A24: Noise Rate | B24: 0.0819 | C24: 0.1189 | D24: 0.0677 | E24: 0.0783 | F24: 0.0656 | G24: 0.0716 | H24: 0.1053 | K24: 0.0828 | L24: 0.0736 | M24: 0.0865 | N24: 0.0898 | O24: 0.1164 | P24: 0.1371 | Q24: 0.0998 | R24: 0.0805 | S24: 0.0814 | T24: 0.0726 | U24: 0.0796 | V24: 10.36% | W24: ='C209'!$B405 -> 7.28% | X24: 8.00% | Y24: 6.81% | Z24: ='C209'!$B468 -> 8.29% | AA24: ='C209'!$B489 -> 6.10% | AB24: {=INDEX('C209'!$I:$I,6+(COLUMN()-28)*21)} -> 8.93% | AC24: {=INDEX('C209'!$I:$I,6+(COLUMN()-28)*21)} -> 7.77% | AD24: {=INDEX('C209'!$I:$I,6+(COLUMN()-28)*21)} -> 0.059849667 | AE24: {=INDEX('C209'!$I:$I,6+(COLUMN()-28)*21)} -> 0.057519878 | AF24: {=INDEX('C209'!$I:$I,6+(COLUMN()-28)*21)} -> 8.19% | AG24: {=INDEX('C209'!$I:$I,6+(COLUMN()-28)*21)} -> 8.53% | AH24: {=INDEX('C209'!$I:$I,6+(COLUMN()-28)*21)} -> 5.40% | AI24: {=INDEX('C209'!$I:$I,6+(COLUMN()-28)*21)} -> 6.50% | ... BA24: {=INDEX('C209'!$I:$I,6+(COLUMN()-28)*21)} -> 1.74% | BB24: {=_xlfn.NUMBERVALUE(INDEX('C209'!$P:$P,6+(COLUMN()-54)*21))} -> 0.0266 | BC24: {=_xlfn.NUMBERVALUE(INDEX('C209'!$P:$P,6+(COLUMN()-54)*21))} -> 0.0372 | BD24: {=_xlfn.NUMBERVALUE(INDEX('C209'!$P:$P,6+(COLUMN()-54)*21))} -> 0.0397 | BE24: {=_xlfn.NUMBERVALUE(INDEX('C209'!$P:$P,6+(COLUMN()-54)*21))} -> 0.0324 | BF24: {=_xlfn.NUMBERVALUE(INDEX('C209'!$P:$P,6+(COLUMN()-54)*21))} -> 0.0391 | BG24: {=_xlfn.NUMBERVALUE(INDEX('C209'!$P:$P,6+(COLUMN()-54)*21))} -> 0.0333 | BH24: {=_xlfn.NUMBERVALUE(INDEX('C209'!$P:$P,6+(COLUMN()-54)*21))} -> 0.0444 | BI24: {=_xlfn.NUMBERVALUE(INDEX('C209'!$P:$P,6+(COLUMN()-54)*21))} -> 0.0541 | ... CA24: {=_xlfn.NUMBERVALUE(INDEX('C209'!$P:$P,6+(COLUMN()-54)*21))} -> 0 | DO24: Noise Fail | DP24: {=INDEX('C209'!$I:$I,9+4*21)+INDEX('C209'!$I:$I,9+5*21)+INDEX('C209'!$I:$I,9+6*21)+INDEX('C209'!$I:$I,9+7*21)+INDEX('C209'!$I:$I,9+8*21)+INDEX('C209'!$I:$I,9+9*21)} -> 2175 | DQ24: {=INDEX('C209'!$I:$I,9+10*21)+INDEX('C209'!$I:$I,9+11*21)+INDEX('C209'!$I:$I,9+12*21)+INDEX('C209'!$I:$I,9+13*21)+INDEX('C209'!$I:$I,9+14*21)+INDEX('C209'!$I:$I,9+15*21)} -> 2951 | DR24: {=INDEX('C209'!$I:$I,9+16*21)+INDEX('C209'!$I:$I,9+17*21)+INDEX('C209'!$I:$I,9+18*21)+INDEX('C209'!$I:$I,9+19*21)+INDEX('C209'!$I:$I,9+20*21)+INDEX('C209'!$I:$I,9+21*21)} -> 2752
A25: RPM Fail Rate | B25: 0.002 | C25: 0.0021 | D25: 0.0031 | E25: 0.0026 | F25: 0.0008 | G25: 0.0042 | H25: 0.0043 | K25: 0.0012 | L25: 0 | M25: 0.0013 | N25: 0.0038 | O25: 0.004 | P25: 0.0032 | Q25: 0.0013 | R25: 0.004 | S25: 0.0029 | T25: 0.002 | U25: 0.0036 | V25: 0.33% | W25: ='C209'!$B406 -> 0.36% | X25: 0.30% | Y25: 0.79% | Z25: ='C209'!$B469 -> 0.86% | AA25: ='C209'!$B490 -> 0.46% | AB25: {=INDEX('C209'!$I:$I,7+(COLUMN()-28)*21)} -> 0.21% | AC25: {=INDEX('C209'!$I:$I,7+(COLUMN()-28)*21)} -> 0.13% | AD25: {=INDEX('C209'!$I:$I,7+(COLUMN()-28)*21)} -> 0.00085094313 | AE25: {=INDEX('C209'!$I:$I,7+(COLUMN()-28)*21)} -> 0.0065978684 | AF25: {=INDEX('C209'!$I:$I,7+(COLUMN()-28)*21)} -> 1.97% | AG25: {=INDEX('C209'!$I:$I,7+(COLUMN()-28)*21)} -> 2.71% | AH25: {=INDEX('C209'!$I:$I,7+(COLUMN()-28)*21)} -> 0.97% | AI25: {=INDEX('C209'!$I:$I,7+(COLUMN()-28)*21)} -> 0.69% | ... BA25: {=INDEX('C209'!$I:$I,7+(COLUMN()-28)*21)} -> 0.67% | BB25: {=_xlfn.NUMBERVALUE(INDEX('C209'!$P:$P,7+(COLUMN()-54)*21))} -> 0.0155 | BC25: {=_xlfn.NUMBERVALUE(INDEX('C209'!$P:$P,7+(COLUMN()-54)*21))} -> 0.3465 | BD25: {=_xlfn.NUMBERVALUE(INDEX('C209'!$P:$P,7+(COLUMN()-54)*21))} -> 0.0245 | BE25: {=_xlfn.NUMBERVALUE(INDEX('C209'!$P:$P,7+(COLUMN()-54)*21))} -> 0.0482 | BF25: {=_xlfn.NUMBERVALUE(INDEX('C209'!$P:$P,7+(COLUMN()-54)*21))} -> 0.0302 | BG25: {=_xlfn.NUMBERVALUE(INDEX('C209'!$P:$P,7+(COLUMN()-54)*21))} -> 0.0057 | BH25: {=_xlfn.NUMBERVALUE(INDEX('C209'!$P:$P,7+(COLUMN()-54)*21))} -> 0.0242 | BI25: {=_xlfn.NUMBERVALUE(INDEX('C209'!$P:$P,7+(COLUMN()-54)*21))} -> 0.0029 | ... CA25: {=_xlfn.NUMBERVALUE(INDEX('C209'!$P:$P,7+(COLUMN()-54)*21))} -> 0 | DO25: RPM Fail | DP25: {=INDEX('C209'!$I:$I,15+4*21)+INDEX('C209'!$I:$I,15+5*21)+INDEX('C209'!$I:$I,15+6*21)+INDEX('C209'!$I:$I,15+7*21)+INDEX('C209'!$I:$I,15+8*21)+INDEX('C209'!$I:$I,15+9*21)} -> 326 | DQ25: {=INDEX('C209'!$I:$I,15+10*21)+INDEX('C209'!$I:$I,15+11*21)+INDEX('C209'!$I:$I,15+12*21)+INDEX('C209'!$I:$I,15+13*21)+INDEX('C209'!$I:$I,15+14*21)+INDEX('C209'!$I:$I,15+15*21)} -> 315 | DR25: {=INDEX('C209'!$I:$I,15+16*21)+INDEX('C209'!$I:$I,15+17*21)+INDEX('C209'!$I:$I,15+18*21)+INDEX('C209'!$I:$I,15+19*21)+INDEX('C209'!$I:$I,15+20*21)+INDEX('C209'!$I:$I,15+21*21)} -> 911
A26: Other Fail Rate | B26: 0 | C26: 0 | D26: 0 | E26: 0.0002 | F26: 0 | G26: 0 | H26: 0 | K26: 0 | L26: 0 | M26: 0 | N26: 0 | O26: 0 | P26: 0 | Q26: 0 | R26: 0 | S26: 0 | T26: 0.0002 | U26: 0 | V26: 0.00% | W26: ='C209'!$B407 -> 0.00% | X26: 0.00% | Y26: 0.01% | Z26: ='C209'!$B470 -> 0.12% | AA26: ='C209'!$B491 -> 0.03% | AB26: {=INDEX('C209'!$I:$I,8+(COLUMN()-28)*21)} -> 0.00% | AC26: {=INDEX('C209'!$I:$I,8+(COLUMN()-28)*21)} -> 0.01% | AD26: {=INDEX('C209'!$I:$I,8+(COLUMN()-28)*21)} -> 0.10% | AE26: {=INDEX('C209'!$I:$I,8+(COLUMN()-28)*21)} -> 0.07% | AF26: {=INDEX('C209'!$I:$I,8+(COLUMN()-28)*21)} -> 0.00% | AG26: {=INDEX('C209'!$I:$I,8+(COLUMN()-28)*21)} -> 0.02% | AH26: {=INDEX('C209'!$I:$I,8+(COLUMN()-28)*21)} -> 0.05% | AI26: {=INDEX('C209'!$I:$I,8+(COLUMN()-28)*21)} -> 0.00% | ... BA26: {=INDEX('C209'!$I:$I,8+(COLUMN()-28)*21)} -> 0.00% | BB26: {=_xlfn.NUMBERVALUE(INDEX('C209'!$P:$P,8+(COLUMN()-54)*21))} -> 0 | BC26: {=_xlfn.NUMBERVALUE(INDEX('C209'!$P:$P,8+(COLUMN()-54)*21))} -> 0 | BD26: {=_xlfn.NUMBERVALUE(INDEX('C209'!$P:$P,8+(COLUMN()-54)*21))} -> 0 | BE26: {=_xlfn.NUMBERVALUE(INDEX('C209'!$P:$P,8+(COLUMN()-54)*21))} -> 0 | BF26: {=_xlfn.NUMBERVALUE(INDEX('C209'!$P:$P,8+(COLUMN()-54)*21))} -> 0 | BG26: {=_xlfn.NUMBERVALUE(INDEX('C209'!$P:$P,8+(COLUMN()-54)*21))} -> 0.0002 | BH26: {=_xlfn.NUMBERVALUE(INDEX('C209'!$P:$P,8+(COLUMN()-54)*21))} -> 0 | BI26: {=_xlfn.NUMBERVALUE(INDEX('C209'!$P:$P,8+(COLUMN()-54)*21))} -> 0 | ... CA26: {=_xlfn.NUMBERVALUE(INDEX('C209'!$P:$P,8+(COLUMN()-54)*21))} -> 0 | DO26: Others Fail | DP26: {=INDEX('C209'!$I:$I,18+4*21)+INDEX('C209'!$I:$I,18+5*21)+INDEX('C209'!$I:$I,18+6*21)+INDEX('C209'!$I:$I,18+7*21)+INDEX('C209'!$I:$I,18+8*21)+INDEX('C209'!$I:$I,18+9*21)} -> 3 | DQ26: {=INDEX('C209'!$I:$I,18+10*21)+INDEX('C209'!$I:$I,18+11*21)+INDEX('C209'!$I:$I,18+12*21)+INDEX('C209'!$I:$I,18+13*21)+INDEX('C209'!$I:$I,18+14*21)+INDEX('C209'!$I:$I,18+15*21)} -> 3 | DR26: {=INDEX('C209'!$I:$I,18+16*21)+INDEX('C209'!$I:$I,18+17*21)+INDEX('C209'!$I:$I,18+18*21)+INDEX('C209'!$I:$I,18+19*21)+INDEX('C209'!$I:$I,18+20*21)+INDEX('C209'!$I:$I,18+21*21)} -> 9
A27: Failure Mode | B27: 4, 6 | C27: 4, 6 | D27: 4, 6 | E27: 4, 6 | F27: 6 | G27: 6 | H27: 4, 6 | K27: 4, 6 | L27: 4, 6 | M27: 4, 6 | N27: 6 | O27: 4, 6 | P27: 4, 6 | Q27: 6 | R27: 6 | S27: 6 | T27: 6 | U27: 6 | V27: 6 | W27: 6 | X27: 6 | Y27: 6 | Z27: 6 | DO27: Tag | DP27: 音頻含有異音 | DQ27: 音頻含有異音 | DR27: 音頻含有異音
A28: Shut down device | B28: 0 | C28: 0 | D28: 0 | E28: 0 | F28: 0 | G28: 0 | H28: 0 | K28: 0 | L28: 0 | M28: 0 | N28: 0 | O28: 0 | P28: 0 | Q28: 0 | R28: 1 | S28: 1 | T28: 0 | U28: 0 | V28: =COUNTIFS('C209'!$C$381:$F$381,"=0") -> 0 | W28: =COUNTIFS('C209'!$C$402:$F$402,"=0") -> 0 | X28: =COUNTIFS('C209'!$C$423:$F$423,"=0") -> 0 | Y28: =COUNTIFS('C209'!$C$444:$F$444,"=0") -> 0 | Z28: =COUNTIFS('C209'!$C$465:$G$465,"=0") -> 0 | AA28: =COUNTIFS('C209'!$C$486:$F$486,"=0") -> 0 | DR28: 中轉版故障
A29: C214 | B29: 46083 | C29: 46084 | D29: 46085 | E29: 46086 | F29: 46087 | G29: 46088 | H29: 46090 | I29: 46091 | J29: 46092 | K29: 46093 | L29: 46094 | M29: 46095 | N29: 46097 | O29: 46098 | P29: 46099 | Q29: 46100 | R29: 46101 | S29: 46102 | T29: 46104 | U29: 46105 | V29: 46106 | W29: 46107 | X29: 46108 | Y29: 46109 | Z29: 46111 | AA29: 46112 | AB29: 46113 | AC29: 46114 | AD29: 46115 | AE29: 46116 | AF29: 46118 | AG29: 46119 | AH29: 46120 | AI29: 46121 | AJ29: 46122 | AK29: 46123 | AL29: 46125 | AM29: 46126 | AN29: 46127 | AO29: 46128 | AP29: 46129 | AQ29: 46130 | AR29: 46132 | AS29: 46133 | AT29: 46134 | AU29: 46135 | AV29: 46136 | AW29: 46137 | AX29: 46139 | AY29: 46140 | AZ29: 46141 | BA29: 46142 | BB29: 46143 | BC29: 46146 | BD29: 46147 | BE29: 46148 | BF29: 46149 | BG29: 46150 | BH29: 46151 | BI29: 46153 | BJ29: 46154 | BK29: 46155 | BL29: 46156 | BM29: 46157 | BN29: 46158 | BO29: 46160 | BP29: 46161 | BQ29: 46162 | BR29: 46163 | BS29: 46164 | BT29: 46165 | BU29: 46167 | BV29: 46168 | BW29: 46169 | BX29: 46170 | BY29: 46171 | BZ29: 46172 | CA29: 46173 | DO29: C214 | DP29: W15(4/6~11) | DQ29: W16(4/13~18) | DR29: W17(4/20~25)
A30: Total Fail Rate | B30: 0.1838 | C30: 0.0385 | D30: 0.0856 | E30: 0.1404 | F30: 0.0514 | H30: 0.0557 | K30: 0.0922 | L30: 0.1311 | M30: 0.1566 | N30: 0.1932 | O30: 0.0708 | P30: 0.1312 | Q30: 0.0769 | R30: 0.1614 | S30: 0.1062 | T30: 0.1564 | U30: 0.0715 | V30: 7.27% | W30: ='C214'!$B383 -> 11.17% | X30: 41.56% | Y30: 45.15% | Z30: ='C214'!$B446 -> 18.10% | AA30: ='C214'!$B467 -> 5.93% | AB30: {=INDEX('C214'!$I:$I,5+(COLUMN()-28)*21)} -> 7.60% | AC30: {=INDEX('C214'!$I:$I,5+(COLUMN()-28)*21)} -> 7.07% | AD30: {=INDEX('C214'!$I:$I,5+(COLUMN()-28)*21)} -> 5.32% | AE30: {=INDEX('C214'!$I:$I,5+(COLUMN()-28)*21)} -> 13.54% | AF30: {=INDEX('C214'!$I:$I,5+(COLUMN()-28)*21)} -> 11.49% | AG30: {=INDEX('C214'!$I:$I,5+(COLUMN()-28)*21)} -> 11.44% | AH30: {=INDEX('C214'!$I:$I,5+(COLUMN()-28)*21)} -> 4.61% | AI30: {=INDEX('C214'!$I:$I,5+(COLUMN()-28)*21)} -> 2.98% | ... BA30: {=INDEX('C214'!$I:$I,5+(COLUMN()-28)*21)} -> 6.81% | BB30: {=_xlfn.NUMBERVALUE(INDEX('C214'!$P:$P,5+(COLUMN()-54)*21))} -> 0.0898 | BC30: {=_xlfn.NUMBERVALUE(INDEX('C214'!$P:$P,5+(COLUMN()-54)*21))} -> 0.0465 | BD30: {=_xlfn.NUMBERVALUE(INDEX('C214'!$P:$P,5+(COLUMN()-54)*21))} -> 0.0492 | BE30: {=_xlfn.NUMBERVALUE(INDEX('C214'!$P:$P,5+(COLUMN()-54)*21))} -> 0.0469 | BF30: {=_xlfn.NUMBERVALUE(INDEX('C214'!$P:$P,5+(COLUMN()-54)*21))} -> 0.0383 | BG30: {=_xlfn.NUMBERVALUE(INDEX('C214'!$P:$P,5+(COLUMN()-54)*21))} -> 0.0594 | BH30: {=_xlfn.NUMBERVALUE(INDEX('C214'!$P:$P,5+(COLUMN()-54)*21))} -> 0.4635 | BI30: {=_xlfn.NUMBERVALUE(INDEX('C214'!$P:$P,5+(COLUMN()-54)*21))} -> 0.0335 | ... CA30: {=_xlfn.NUMBERVALUE(INDEX('C214'!$P:$P,5+(COLUMN()-54)*21))} -> 0 | DO30: Total | DP30: {=INDEX('C214'!$I:$I,3+4*21)+INDEX('C214'!$I:$I,3+5*21)+INDEX('C214'!$I:$I,3+6*21)+INDEX('C214'!$I:$I,3+7*21)+INDEX('C214'!$I:$I,3+8*21)+INDEX('C214'!$I:$I,3+9*21)} -> 28294 | DQ30: {=INDEX('C214'!$I:$I,3+10*21)+INDEX('C214'!$I:$I,3+11*21)+INDEX('C214'!$I:$I,3+12*21)+INDEX('C214'!$I:$I,3+13*21)+INDEX('C214'!$I:$I,3+14*21)+INDEX('C214'!$I:$I,3+15*21)} -> 34186 | DR30: {=INDEX('C214'!$I:$I,3+16*21)+INDEX('C214'!$I:$I,3+17*21)+INDEX('C214'!$I:$I,3+18*21)+INDEX('C214'!$I:$I,3+19*21)+INDEX('C214'!$I:$I,3+20*21)+INDEX('C214'!$I:$I,3+21*21)} -> 33766
A31: Noise Rate | B31: 0.0701 | C31: 0.0017 | D31: 0.006 | E31: 0.0321 | F31: 0.0062 | H31: 0.0389 | K31: 0.085 | L31: 0.0746 | M31: 0.1011 | N31: 0.1392 | O31: 0.0541 | P31: 0.1063 | Q31: 0.0318 | R31: 0.0905 | S31: 0.1028 | T31: 0.1502 | U31: 0.0673 | V31: 6.73% | W31: ='C214'!$B384 -> 5.03% | X31: 2.00% | Y31: 2.55% | Z31: ='C214'!$B447 -> 5.63% | AA31: ='C214'!$B468 -> 3.54% | AB31: {=INDEX('C214'!$I:$I,6+(COLUMN()-28)*21)} -> 4.03% | AC31: {=INDEX('C214'!$I:$I,6+(COLUMN()-28)*21)} -> 3.70% | AD31: {=INDEX('C214'!$I:$I,6+(COLUMN()-28)*21)} -> 2.91% | AE31: {=INDEX('C214'!$I:$I,6+(COLUMN()-28)*21)} -> 6.04% | AF31: {=INDEX('C214'!$I:$I,6+(COLUMN()-28)*21)} -> 7.55% | AG31: {=INDEX('C214'!$I:$I,6+(COLUMN()-28)*21)} -> 7.61% | AH31: {=INDEX('C214'!$I:$I,6+(COLUMN()-28)*21)} -> 2.06% | AI31: {=INDEX('C214'!$I:$I,6+(COLUMN()-28)*21)} -> 1.29% | ... BA31: {=INDEX('C214'!$I:$I,6+(COLUMN()-28)*21)} -> 1.60% | BB31: {=_xlfn.NUMBERVALUE(INDEX('C214'!$P:$P,6+(COLUMN()-54)*21))} -> 0.0382 | BC31: {=_xlfn.NUMBERVALUE(INDEX('C214'!$P:$P,6+(COLUMN()-54)*21))} -> 0.0425 | BD31: {=_xlfn.NUMBERVALUE(INDEX('C214'!$P:$P,6+(COLUMN()-54)*21))} -> 0.0383 | BE31: {=_xlfn.NUMBERVALUE(INDEX('C214'!$P:$P,6+(COLUMN()-54)*21))} -> 0.0339 | BF31: {=_xlfn.NUMBERVALUE(INDEX('C214'!$P:$P,6+(COLUMN()-54)*21))} -> 0.022 | BG31: {=_xlfn.NUMBERVALUE(INDEX('C214'!$P:$P,6+(COLUMN()-54)*21))} -> 0.0223 | BH31: {=_xlfn.NUMBERVALUE(INDEX('C214'!$P:$P,6+(COLUMN()-54)*21))} -> 0.0214 | BI31: {=_xlfn.NUMBERVALUE(INDEX('C214'!$P:$P,6+(COLUMN()-54)*21))} -> 0.0043 | ... CA31: {=_xlfn.NUMBERVALUE(INDEX('C214'!$P:$P,6+(COLUMN()-54)*21))} -> 0 | DO31: Noise Fail | DP31: {=INDEX('C214'!$I:$I,9+4*21)+INDEX('C214'!$I:$I,9+5*21)+INDEX('C214'!$I:$I,9+6*21)+INDEX('C214'!$I:$I,9+7*21)+INDEX('C214'!$I:$I,9+8*21)+INDEX('C214'!$I:$I,9+9*21)} -> 955 | DQ31: {=INDEX('C214'!$I:$I,9+10*21)+INDEX('C214'!$I:$I,9+11*21)+INDEX('C214'!$I:$I,9+12*21)+INDEX('C214'!$I:$I,9+13*21)+INDEX('C214'!$I:$I,9+14*21)+INDEX('C214'!$I:$I,9+15*21)} -> 1582 | DR31: {=INDEX('C214'!$I:$I,9+16*21)+INDEX('C214'!$I:$I,9+17*21)+INDEX('C214'!$I:$I,9+18*21)+INDEX('C214'!$I:$I,9+19*21)+INDEX('C214'!$I:$I,9+20*21)+INDEX('C214'!$I:$I,9+21*21)} -> 1040
A32: RPM Fail Rate | B32: 0.1265 | C32: 0.0921 | D32: 0.0796 | E32: 0.1 | F32: 0.0451 | H32: 0.0165 | K32: 0.0086 | L32: 0.0574 | M32: 0.0552 | N32: 0.054 | O32: 0.0169 | P32: 0.0247 | Q32: 0.3335 | R32: 0.1082 | S32: 0.0025 | T32: 0.0062 | U32: 0.0041 | V32: 0.54% | W32: ='C214'!$B385 -> 6.08% | X32: 39.17% | Y32: 42.57% | Z32: ='C214'!$B448 -> 11.62% | AA32: ='C214'!$B469 -> 2.44% | AB32: {=INDEX('C214'!$I:$I,7+(COLUMN()-28)*21)} -> 3.58% | AC32: {=INDEX('C214'!$I:$I,7+(COLUMN()-28)*21)} -> 3.38% | AD32: {=INDEX('C214'!$I:$I,7+(COLUMN()-28)*21)} -> 2.41% | AE32: {=INDEX('C214'!$I:$I,7+(COLUMN()-28)*21)} -> 7.20% | AF32: {=INDEX('C214'!$I:$I,7+(COLUMN()-28)*21)} -> 3.94% | AG32: {=INDEX('C214'!$I:$I,7+(COLUMN()-28)*21)} -> 3.83% | AH32: {=INDEX('C214'!$I:$I,7+(COLUMN()-28)*21)} -> 2.47% | AI32: {=INDEX('C214'!$I:$I,7+(COLUMN()-28)*21)} -> 1.69% | ... BA32: {=INDEX('C214'!$I:$I,7+(COLUMN()-28)*21)} -> 2.58% | BB32: {=_xlfn.NUMBERVALUE(INDEX('C214'!$P:$P,7+(COLUMN()-54)*21))} -> 0.0493 | BC32: {=_xlfn.NUMBERVALUE(INDEX('C214'!$P:$P,7+(COLUMN()-54)*21))} -> 0.003 | BD32: {=_xlfn.NUMBERVALUE(INDEX('C214'!$P:$P,7+(COLUMN()-54)*21))} -> 0.011 | BE32: {=_xlfn.NUMBERVALUE(INDEX('C214'!$P:$P,7+(COLUMN()-54)*21))} -> 0.0127 | BF32: {=_xlfn.NUMBERVALUE(INDEX('C214'!$P:$P,7+(COLUMN()-54)*21))} -> 0.0163 | BG32: {=_xlfn.NUMBERVALUE(INDEX('C214'!$P:$P,7+(COLUMN()-54)*21))} -> 0.0365 | BH32: {=_xlfn.NUMBERVALUE(INDEX('C214'!$P:$P,7+(COLUMN()-54)*21))} -> 0.4328 | BI32: {=_xlfn.NUMBERVALUE(INDEX('C214'!$P:$P,7+(COLUMN()-54)*21))} -> 0.0293 | ... CA32: {=_xlfn.NUMBERVALUE(INDEX('C214'!$P:$P,7+(COLUMN()-54)*21))} -> 0 | DO32: RPM Fail | DP32: {=INDEX('C214'!$I:$I,15+4*21)+INDEX('C214'!$I:$I,15+5*21)+INDEX('C214'!$I:$I,15+6*21)+INDEX('C214'!$I:$I,15+7*21)+INDEX('C214'!$I:$I,15+8*21)+INDEX('C214'!$I:$I,15+9*21)} -> 879 | DQ32: {=INDEX('C214'!$I:$I,15+10*21)+INDEX('C214'!$I:$I,15+11*21)+INDEX('C214'!$I:$I,15+12*21)+INDEX('C214'!$I:$I,15+13*21)+INDEX('C214'!$I:$I,15+14*21)+INDEX('C214'!$I:$I,15+15*21)} -> 1168 | DR32: {=INDEX('C214'!$I:$I,15+16*21)+INDEX('C214'!$I:$I,15+17*21)+INDEX('C214'!$I:$I,15+18*21)+INDEX('C214'!$I:$I,15+19*21)+INDEX('C214'!$I:$I,15+20*21)+INDEX('C214'!$I:$I,15+21*21)} -> 1569
A33: Other Fail Rate | B33: 0.0271 | C33: 0.0356 | D33: 0.0497 | E33: 0.008 | F33: 0.001 | H33: 0.0197 | K33: 0.0358 | L33: 0.0326 | M33: 0.0252 | N33: 0.0228 | O33: 0.0007 | P33: 0.0004 | Q33: 0.0002 | R33: 0.0268 | S33: 0.0144 | T33: 0.0134 | U33: 0.0129 | V33: 2.38% | W33: ='C214'!$B386 -> 1.41% | X33: 1.41% | Y33: 0.00% | Z33: ='C214'!$B449 -> 0.35% | AA33: ='C214'!$B470 -> 0.03% | AB33: {=INDEX('C214'!$I:$I,8+(COLUMN()-28)*21)} -> 0.02% | AC33: {=INDEX('C214'!$I:$I,8+(COLUMN()-28)*21)} -> 0.06% | AD33: {=INDEX('C214'!$I:$I,8+(COLUMN()-28)*21)} -> 0.09% | AE33: {=INDEX('C214'!$I:$I,8+(COLUMN()-28)*21)} -> 0.13% | AF33: {=INDEX('C214'!$I:$I,8+(COLUMN()-28)*21)} -> 0.64% | AG33: {=INDEX('C214'!$I:$I,8+(COLUMN()-28)*21)} -> 0.28% | AH33: {=INDEX('C214'!$I:$I,8+(COLUMN()-28)*21)} -> 0.26% | AI33: {=INDEX('C214'!$I:$I,8+(COLUMN()-28)*21)} -> 0.18% | ... BA33: {=INDEX('C214'!$I:$I,8+(COLUMN()-28)*21)} -> 0.00% | BB33: {=_xlfn.NUMBERVALUE(INDEX('C214'!$P:$P,8+(COLUMN()-54)*21))} -> 0.0001 | BC33: {=_xlfn.NUMBERVALUE(INDEX('C214'!$P:$P,8+(COLUMN()-54)*21))} -> 0 | BD33: {=_xlfn.NUMBERVALUE(INDEX('C214'!$P:$P,8+(COLUMN()-54)*21))} -> 0 | BE33: {=_xlfn.NUMBERVALUE(INDEX('C214'!$P:$P,8+(COLUMN()-54)*21))} -> 0.0003 | BF33: {=_xlfn.NUMBERVALUE(INDEX('C214'!$P:$P,8+(COLUMN()-54)*21))} -> 0.0058 | BG33: {=_xlfn.NUMBERVALUE(INDEX('C214'!$P:$P,8+(COLUMN()-54)*21))} -> 0.0005 | BH33: {=_xlfn.NUMBERVALUE(INDEX('C214'!$P:$P,8+(COLUMN()-54)*21))} -> 0.0002 | BI33: {=_xlfn.NUMBERVALUE(INDEX('C214'!$P:$P,8+(COLUMN()-54)*21))} -> 0.0005 | ... CA33: {=_xlfn.NUMBERVALUE(INDEX('C214'!$P:$P,8+(COLUMN()-54)*21))} -> 0 | DO33: Others Fail | DP33: {=INDEX('C214'!$I:$I,18+4*21)+INDEX('C214'!$I:$I,18+5*21)+INDEX('C214'!$I:$I,18+6*21)+INDEX('C214'!$I:$I,18+7*21)+INDEX('C214'!$I:$I,18+8*21)+INDEX('C214'!$I:$I,18+9*21)} -> 97 | DQ33: {=INDEX('C214'!$I:$I,18+10*21)+INDEX('C214'!$I:$I,18+11*21)+INDEX('C214'!$I:$I,18+12*21)+INDEX('C214'!$I:$I,18+13*21)+INDEX('C214'!$I:$I,18+14*21)+INDEX('C214'!$I:$I,18+15*21)} -> 13 | DR33: {=INDEX('C214'!$I:$I,18+16*21)+INDEX('C214'!$I:$I,18+17*21)+INDEX('C214'!$I:$I,18+18*21)+INDEX('C214'!$I:$I,18+19*21)+INDEX('C214'!$I:$I,18+20*21)+INDEX('C214'!$I:$I,18+21*21)} -> 6
A34: Failure Mode | B34: 1, 2, 3 | C34: 2, 3 | D34: 2, 3 | E34: 1, 2, 3, 5 | F34: 1, 2, 3, 5 | H34: 3, 5 | K34: 1, 3, 5 | L34: 2, 3 | M34: 2, 3 | N34: 1, 2, 3, 5 | O34: 1, 3, 5 | P34: 1, 5 | Q34: 1, 2, 3, 5 | R34: 1, 2, 3, 5 | S34: 3 | T34: 1, 3, 5 | U34: 1, 3, 5 | V34: 1, 3, 5 | W34: 1, 2, 3, 5 | X34: 2, 3 | Y34: 2 | Z34: 1, 2, 5 | DO34: Tag | DP34: 音頻含有異音 中轉版故障 | DQ34: 音頻含有異音 中轉版故障 | DR34: 音頻含有異音 中轉版故障
A35: Shut down device | B35: =COUNTIFS('C214'!$C$3:$F$3,"=0") -> 1 | C35: =COUNTIFS('C214'!$C$24:$F$24,"=0") -> 1 | D35: =COUNTIFS('C214'!$C$45:$F$45,"=0") -> 1 | E35: =COUNTIFS('C214'!$C$66:$F$66,"=0") -> 0 | F35: =COUNTIFS('C214'!$C$87:$F$87,"=0") -> 1 | H35: =COUNTIFS('C214'!$C$108:$F$108,"=0") -> 0 | K35: =COUNTIFS('C214'!$C$129:$F$129,"=0") -> 1 | L35: =COUNTIFS('C214'!$C$150:$F$150,"=0") -> 1 | M35: =COUNTIFS('C214'!$C$171:$F$171,"=0") -> 1 | N35: =COUNTIFS('C214'!$C$192:$F$192,"=0") -> 0 | O35: =COUNTIFS('C214'!$C$213:$F$213,"=0") -> 0 | P35: =COUNTIFS('C214'!$C$234:$F$234,"=0") -> 1 | Q35: =COUNTIFS('C214'!$C$255:$F$255,"=0") -> 0 | R35: =COUNTIFS('C214'!$C$276:$F$276,"=0") -> 0 | S35: =COUNTIFS('C214'!$C$297:$F$297,"=0") -> 1 | T35: =COUNTIFS('C214'!$C$318:$F$318,"=0") -> 0 | U35: =COUNTIFS('C214'!$C$339:$G$339,"=0") -> 1 | V35: =COUNTIFS('C214'!$C$360:$G$360,"=0") -> 1 | W35: =COUNTIFS('C214'!$C$381:$G$381,"=0") -> 1 | X35: =COUNTIFS('C214'!$C$402:$G$402,"=0") -> 1 | Y35: =COUNTIFS('C214'!$D$423:$H$423,"=0") -> 1 | Z35: =COUNTIFS('C214'!$C$444:$G$444,"=0") -> 1 | AA35: =COUNTIFS('C214'!$C$465:$G$465,"=0") -> 1 | DP35: 一號機MIC位置異常 | DQ35: 一號機MIC位置異常
A36: C215 | B36: 46083 | C36: 46084 | D36: 46085 | E36: 46086 | F36: 46087 | G36: 46088 | H36: 46090 | I36: 46091 | J36: 46092 | K36: 46093 | L36: 46094 | M36: 46095 | N36: 46097 | O36: 46098 | P36: 46099 | Q36: 46100 | R36: 46101 | S36: 46102 | T36: 46104 | U36: 46105 | V36: 46106 | W36: 46107 | X36: 46108 | Y36: 46109 | Z36: 46111 | AA36: 46112 | AB36: 46113 | AC36: 46114 | AD36: 46115 | AE36: 46116 | AF36: 46118 | AG36: 46119 | AH36: 46120 | AI36: 46121 | AJ36: 46122 | AK36: 46123 | AL36: 46125 | AM36: 46126 | AN36: 46127 | AO36: 46128 | AP36: 46129 | AQ36: 46130 | AR36: 46132 | AS36: 46133 | AT36: 46134 | AU36: 46135 | AV36: 46136 | AW36: 46137 | AX36: 46139 | AY36: 46140 | AZ36: 46141 | BA36: 46142 | BB36: 46143 | BC36: 46146 | BD36: 46147 | BE36: 46148 | BF36: 46149 | BG36: 46150 | BH36: 46151 | BI36: 46153 | BJ36: 46154 | BK36: 46155 | BL36: 46156 | BM36: 46157 | BN36: 46158 | BO36: 46160 | BP36: 46161 | BQ36: 46162 | BR36: 46163 | BS36: 46164 | BT36: 46165 | BU36: 46167 | BV36: 46168 | BW36: 46169 | BX36: 46170 | BY36: 46171 | BZ36: 46172 | CA36: 46173 | DO36: C215 | DP36: W15(4/6~11) | DQ36: W16(4/13~18) | DR36: W17(4/20~25)
